Workbook

Sheet Libro auxiliar vs banco
A1: Conciliacion Bancaria
A2: Libro Auxiliar | E2: Conciliacion Automatica | G2: Conciliacion manual
A3: ID | B3: Fecha | C3: Nombre | D3: Valor | E3: Estado | F3: Conciliado del banco con registros: | G3: Estado | H3: Conciliado del banco con registros: | I3: Estado automatico base
A4: 366 | B4: 46021 | C4: barrera garcia harol | D4: 21300 | E4: =IF(G4="conciliado","conciliado",I4) | F4: =IF(SUM(COUNTIFS('Conciliacion de compuestos'!$D$2:$D$48,"conciliado",'Conciliacion de compuestos'!$E$2:$E$48,"OK",'Conciliacion de compuestos'!$M$2:$M$48,A4),COUNTIFS('Conciliacion de compuestos'!$D$2:$D$48,"conciliado",'Conciliacion de compuestos'!$E$2:$E$48,"OK",'Conciliacion de compuestos'!$N$2:$N$48,A4),COUNTIFS('Conciliacion de compuestos'!$D$2:$D$48,"conciliado",'Conciliacion de compuestos'!$E$2:$E$48,"OK",'Conciliacion de compuestos'!$O$2:$O$48,A4))>0,IFERROR(TEXTJOIN(CHAR(10),TRUE,FILTER('Conciliacion de compuestos'!$A$2:$A$48,('Conciliacion de compuestos'!$D$2:$D$48="conciliado")*('Conciliacion de compuestos'!$E$2:$E$48="OK")*((('Conciliacion de compuestos'!$M$2:$M$48=A4)+('Conciliacion de compuestos'!$N$2:$N$48=A4)+('Conciliacion de compuestos'!$O$2:$O$48=A4))>0))),""),"") | G4: =IF(I4="conciliado","conciliado","por revisar") | I4: =IF(SUM(COUNTIFS('Conciliacion de compuestos'!$D$2:$D$48,"conciliado",'Conciliacion de compuestos'!$E$2:$E$48,"OK",'Conciliacion de compuestos'!$M$2:$M$48,A4),COUNTIFS('Conciliacion de compuestos'!$D$2:$D$48,"conciliado",'Conciliacion de compuestos'!$E$2:$E$48,"OK",'Conciliacion de compuestos'!$N$2:$N$48,A4),COUNTIFS('Conciliacion de compuestos'!$D$2:$D$48,"conciliado",'Conciliacion de compuestos'!$E$2:$E$48,"OK",'Conciliacion de compuestos'!$O$2:$O$48,A4))>0,"conciliado","por revisar")
A5: 213 | B5: 46011 | C5: barrera garcia harol | D5: 20900 | E5: =IF(G5="conciliado","conciliado",I5) | F5: =IF(SUM(COUNTIFS('Conciliacion de compuestos'!$D$2:$D$48,"conciliado",'Conciliacion de compuestos'!$E$2:$E$48,"OK",'Conciliacion de compuestos'!$M$2:$M$48,A5),COUNTIFS('Conciliacion de compuestos'!$D$2:$D$48,"conciliado",'Conciliacion de compuestos'!$E$2:$E$48,"OK",'Conciliacion de compuestos'!$N$2:$N$48,A5),COUNTIFS('Conciliacion de compuestos'!$D$2:$D$48,"conciliado",'Conciliacion de compuestos'!$E$2:$E$48,"OK",'Conciliacion de compuestos'!$O$2:$O$48,A5))>0,IFERROR(TEXTJOIN(CHAR(10),TRUE,FILTER('Conciliacion de compuestos'!$A$2:$A$48,('Conciliacion de compuestos'!$D$2:$D$48="conciliado")*('Conciliacion de compuestos'!$E$2:$E$48="OK")*((('Conciliacion de compuestos'!$M$2:$M$48=A5)+('Conciliacion de compuestos'!$N$2:$N$48=A5)+('Conciliacion de compuestos'!$O$2:$O$48=A5))>0))),""),"") | G5: =IF(I5="conciliado","conciliado","por revisar") | I5: =IF(SUM(COUNTIFS('Conciliacion de compuestos'!$D$2:$D$48,"conciliado",'Conciliacion de compuestos'!$E$2:$E$48,"OK",'Conciliacion de compuestos'!$M$2:$M$48,A5),COUNTIFS('Conciliacion de compuestos'!$D$2:$D$48,"conciliado",'Conciliacion de compuestos'!$E$2:$E$48,"OK",'Conciliacion de compuestos'!$N$2:$N$48,A5),COUNTIFS('Conciliacion de compuestos'!$D$2:$D$48,"conciliado",'Conciliacion de compuestos'!$E$2:$E$48,"OK",'Conciliacion de compuestos'!$O$2:$O$48,A5))>0,"conciliado","por revisar")
A6: 389 | B6: 46022 | C6: lui munoz pantoja | D6: 22400 | E6: =IF(G6="conciliado","conciliado",I6) | F6: =IF(SUM(COUNTIFS('Conciliacion de compuestos'!$D$2:$D$48,"conciliado",'Conciliacion de compuestos'!$E$2:$E$48,"OK",'Conciliacion de compuestos'!$M$2:$M$48,A6),COUNTIFS('Conciliacion de compuestos'!$D$2:$D$48,"conciliado",'Conciliacion de compuestos'!$E$2:$E$48,"OK",'Conciliacion de compuestos'!$N$2:$N$48,A6),COUNTIFS('Conciliacion de compuestos'!$D$2:$D$48,"conciliado",'Conciliacion de compuestos'!$E$2:$E$48,"OK",'Conciliacion de compuestos'!$O$2:$O$48,A6))>0,IFERROR(TEXTJOIN(CHAR(10),TRUE,FILTER('Conciliacion de compuestos'!$A$2:$A$48,('Conciliacion de compuestos'!$D$2:$D$48="conciliado")*('Conciliacion de compuestos'!$E$2:$E$48="OK")*((('Conciliacion de compuestos'!$M$2:$M$48=A6)+('Conciliacion de compuestos'!$N$2:$N$48=A6)+('Conciliacion de compuestos'!$O$2:$O$48=A6))>0))),""),"") | G6: =IF(I6="conciliado","conciliado","por revisar") | I6: =IF(SUM(COUNTIFS('Conciliacion de compuestos'!$D$2:$D$48,"conciliado",'Conciliacion de compuestos'!$E$2:$E$48,"OK",'Conciliacion de compuestos'!$M$2:$M$48,A6),COUNTIFS('Conciliacion de compuestos'!$D$2:$D$48,"conciliado",'Conciliacion de compuestos'!$E$2:$E$48,"OK",'Conciliacion de compuestos'!$N$2:$N$48,A6),COUNTIFS('Conciliacion de compuestos'!$D$2:$D$48,"conciliado",'Conciliacion de compuestos'!$E$2:$E$48,"OK",'Conciliacion de compuestos'!$O$2:$O$48,A6))>0,"conciliado","por revisar")
A7: 180 | B7: 46009 | C7: carabali herna ocoro | D7: 22000 | E7: =IF(G7="conciliado","conciliado",I7) | F7: =IF(SUM(COUNTIFS('Conciliacion de compuestos'!$D$2:$D$48,"conciliado",'Conciliacion de compuestos'!$E$2:$E$48,"OK",'Conciliacion de compuestos'!$M$2:$M$48,A7),COUNTIFS('Conciliacion de compuestos'!$D$2:$D$48,"conciliado",'Conciliacion de compuestos'!$E$2:$E$48,"OK",'Conciliacion de compuestos'!$N$2:$N$48,A7),COUNTIFS('Conciliacion de compuestos'!$D$2:$D$48,"conciliado",'Conciliacion de compuestos'!$E$2:$E$48,"OK",'Conciliacion de compuestos'!$O$2:$O$48,A7))>0,IFERROR(TEXTJOIN(CHAR(10),TRUE,FILTER('Conciliacion de compuestos'!$A$2:$A$48,('Conciliacion de compuestos'!$D$2:$D$48="conciliado")*('Conciliacion de compuestos'!$E$2:$E$48="OK")*((('Conciliacion de compuestos'!$M$2:$M$48=A7)+('Conciliacion de compuestos'!$N$2:$N$48=A7)+('Conciliacion de compuestos'!$O$2:$O$48=A7))>0))),""),"") | G7: =IF(I7="conciliado","conciliado","por revisar") | I7: =IF(SUM(COUNTIFS('Conciliacion de compuestos'!$D$2:$D$48,"conciliado",'Conciliacion de compuestos'!$E$2:$E$48,"OK",'Conciliacion de compuestos'!$M$2:$M$48,A7),COUNTIFS('Conciliacion de compuestos'!$D$2:$D$48,"conciliado",'Conciliacion de compuestos'!$E$2:$E$48,"OK",'Conciliacion de compuestos'!$N$2:$N$48,A7),COUNTIFS('Conciliacion de compuestos'!$D$2:$D$48,"conciliado",'Conciliacion de compuestos'!$E$2:$E$48,"OK",'Conciliacion de compuestos'!$O$2:$O$48,A7))>0,"conciliado","por revisar")
A8: 64 | B8: 45998 | C8: imues oscar sanchez | D8: 32200 | E8: =IF(G8="conciliado","conciliado",I8) | F8: =IF(SUM(COUNTIFS('Conciliacion de compuestos'!$D$2:$D$48,"conciliado",'Conciliacion de compuestos'!$E$2:$E$48,"OK",'Conciliacion de compuestos'!$M$2:$M$48,A8),COUNTIFS('Conciliacion de compuestos'!$D$2:$D$48,"conciliado",'Conciliacion de compuestos'!$E$2:$E$48,"OK",'Conciliacion de compuestos'!$N$2:$N$48,A8),COUNTIFS('Conciliacion de compuestos'!$D$2:$D$48,"conciliado",'Conciliacion de compuestos'!$E$2:$E$48,"OK",'Conciliacion de compuestos'!$O$2:$O$48,A8))>0,IFERROR(TEXTJOIN(CHAR(10),TRUE,FILTER('Conciliacion de compuestos'!$A$2:$A$48,('Conciliacion de compuestos'!$D$2:$D$48="conciliado")*('Conciliacion de compuestos'!$E$2:$E$48="OK")*((('Conciliacion de compuestos'!$M$2:$M$48=A8)+('Conciliacion de compuestos'!$N$2:$N$48=A8)+('Conciliacion de compuestos'!$O$2:$O$48=A8))>0))),""),"") | G8: =IF(I8="conciliado","conciliado","por revisar") | I8: =IF(SUM(COUNTIFS('Conciliacion de compuestos'!$D$2:$D$48,"conciliado",'Conciliacion de compuestos'!$E$2:$E$48,"OK",'Conciliacion de compuestos'!$M$2:$M$48,A8),COUNTIFS('Conciliacion de compuestos'!$D$2:$D$48,"conciliado",'Conciliacion de compuestos'!$E$2:$E$48,"OK",'Conciliacion de compuestos'!$N$2:$N$48,A8),COUNTIFS('Conciliacion de compuestos'!$D$2:$D$48,"conciliado",'Conciliacion de compuestos'!$E$2:$E$48,"OK",'Conciliacion de compuestos'!$O$2:$O$48,A8))>0,"conciliado","por revisar")
A9: 8 | B9: 45992 | C9: car luis orozco uran | D9: 282550 | E9: =IF(G9="conciliado","conciliado",I9) | F9: =IF(SUM(COUNTIFS('Conciliacion de compuestos'!$D$2:$D$48,"conciliado",'Conciliacion de compuestos'!$E$2:$E$48,"OK",'Conciliacion de compuestos'!$M$2:$M$48,A9),COUNTIFS('Conciliacion de compuestos'!$D$2:$D$48,"conciliado",'Conciliacion de compuestos'!$E$2:$E$48,"OK",'Conciliacion de compuestos'!$N$2:$N$48,A9),COUNTIFS('Conciliacion de compuestos'!$D$2:$D$48,"conciliado",'Conciliacion de compuestos'!$E$2:$E$48,"OK",'Conciliacion de compuestos'!$O$2:$O$48,A9))>0,IFERROR(TEXTJOIN(CHAR(10),TRUE,FILTER('Conciliacion de compuestos'!$A$2:$A$48,('Conciliacion de compuestos'!$D$2:$D$48="conciliado")*('Conciliacion de compuestos'!$E$2:$E$48="OK")*((('Conciliacion de compuestos'!$M$2:$M$48=A9)+('Conciliacion de compuestos'!$N$2:$N$48=A9)+('Conciliacion de compuestos'!$O$2:$O$48=A9))>0))),""),"") | G9: =IF(I9="conciliado","conciliado","por revisar") | I9: =IF(SUM(COUNTIFS('Conciliacion de compuestos'!$D$2:$D$48,"conciliado",'Conciliacion de compuestos'!$E$2:$E$48,"OK",'Conciliacion de compuestos'!$M$2:$M$48,A9),COUNTIFS('Conciliacion de compuestos'!$D$2:$D$48,"conciliado",'Conciliacion de compuestos'!$E$2:$E$48,"OK",'Conciliacion de compuestos'!$N$2:$N$48,A9),COUNTIFS('Conciliacion de compuestos'!$D$2:$D$48,"conciliado",'Conciliacion de compuestos'!$E$2:$E$48,"OK",'Conciliacion de compuestos'!$O$2:$O$48,A9))>0,"conciliado","por revisar")
A10: 4 | B10: 45992 | C10: bolanos paladines st | D10: 504500 | E10: =IF(G10="conciliado","conciliado",I10) | F10: =IF(SUM(COUNTIFS('Conciliacion de compuestos'!$D$2:$D$48,"conciliado",'Conciliacion de compuestos'!$E$2:$E$48,"OK",'Conciliacion de compuestos'!$M$2:$M$48,A10),COUNTIFS('Conciliacion de compuestos'!$D$2:$D$48,"conciliado",'Conciliacion de compuestos'!$E$2:$E$48,"OK",'Conciliacion de compuestos'!$N$2:$N$48,A10),COUNTIFS('Conciliacion de compuestos'!$D$2:$D$48,"conciliado",'Conciliacion de compuestos'!$E$2:$E$48,"OK",'Conciliacion de compuestos'!$O$2:$O$48,A10))>0,IFERROR(TEXTJOIN(CHAR(10),TRUE,FILTER('Conciliacion de compuestos'!$A$2:$A$48,('Conciliacion de compuestos'!$D$2:$D$48="conciliado")*('Conciliacion de compuestos'!$E$2:$E$48="OK")*((('Conciliacion de compuestos'!$M$2:$M$48=A10)+('Conciliacion de compuestos'!$N$2:$N$48=A10)+('Conciliacion de compuestos'!$O$2:$O$48=A10))>0))),""),"") | G10: =IF(I10="conciliado","conciliado","por revisar") | I10: =IF(SUM(COUNTIFS('Conciliacion de compuestos'!$D$2:$D$48,"conciliado",'Conciliacion de compuestos'!$E$2:$E$48,"OK",'Conciliacion de compuestos'!$M$2:$M$48,A10),COUNTIFS('Conciliacion de compuestos'!$D$2:$D$48,"conciliado",'Conciliacion de compuestos'!$E$2:$E$48,"OK",'Conciliacion de compuestos'!$N$2:$N$48,A10),COUNTIFS('Conciliacion de compuestos'!$D$2:$D$48,"conciliado",'Conciliacion de compuestos'!$E$2:$E$48,"OK",'Conciliacion de compuestos'!$O$2:$O$48,A10))>0,"conciliado","por revisar")
A11: 1 | B11: 45992 | C11: carretero diaz oscar | D11: 66200 | E11: =IF(G11="conciliado","conciliado",I11) | F11: =IF(SUM(COUNTIFS('Conciliacion de compuestos'!$D$2:$D$48,"conciliado",'Conciliacion de compuestos'!$E$2:$E$48,"OK",'Conciliacion de compuestos'!$M$2:$M$48,A11),COUNTIFS('Conciliacion de compuestos'!$D$2:$D$48,"conciliado",'Conciliacion de compuestos'!$E$2:$E$48,"OK",'Conciliacion de compuestos'!$N$2:$N$48,A11),COUNTIFS('Conciliacion de compuestos'!$D$2:$D$48,"conciliado",'Conciliacion de compuestos'!$E$2:$E$48,"OK",'Conciliacion de compuestos'!$O$2:$O$48,A11))>0,IFERROR(TEXTJOIN(CHAR(10),TRUE,FILTER('Conciliacion de compuestos'!$A$2:$A$48,('Conciliacion de compuestos'!$D$2:$D$48="conciliado")*('Conciliacion de compuestos'!$E$2:$E$48="OK")*((('Conciliacion de compuestos'!$M$2:$M$48=A11)+('Conciliacion de compuestos'!$N$2:$N$48=A11)+('Conciliacion de compuestos'!$O$2:$O$48=A11))>0))),""),"") | G11: =IF(I11="conciliado","conciliado","por revisar") | I11: =IF(SUM(COUNTIFS('Conciliacion de compuestos'!$D$2:$D$48,"conciliado",'Conciliacion de compuestos'!$E$2:$E$48,"OK",'Conciliacion de compuestos'!$M$2:$M$48,A11),COUNTIFS('Conciliacion de compuestos'!$D$2:$D$48,"conciliado",'Conciliacion de compuestos'!$E$2:$E$48,"OK",'Conciliacion de compuestos'!$N$2:$N$48,A11),COUNTIFS('Conciliacion de compuestos'!$D$2:$D$48,"conciliado",'Conciliacion de compuestos'!$E$2:$E$48,"OK",'Conciliacion de compuestos'!$O$2:$O$48,A11))>0,"conciliado","por revisar")
A12: 6 | B12: 45992 | C12: gomez rene roque | D12: 42765 | E12: =IF(G12="conciliado","conciliado",I12) | F12: =IF(SUM(COUNTIFS('Conciliacion de compuestos'!$D$2:$D$48,"conciliado",'Conciliacion de compuestos'!$E$2:$E$48,"OK",'Conciliacion de compuestos'!$M$2:$M$48,A12),COUNTIFS('Conciliacion de compuestos'!$D$2:$D$48,"conciliado",'Conciliacion de compuestos'!$E$2:$E$48,"OK",'Conciliacion de compuestos'!$N$2:$N$48,A12),COUNTIFS('Conciliacion de compuestos'!$D$2:$D$48,"conciliado",'Conciliacion de compuestos'!$E$2:$E$48,"OK",'Conciliacion de compuestos'!$O$2:$O$48,A12))>0,IFERROR(TEXTJOIN(CHAR(10),TRUE,FILTER('Conciliacion de compuestos'!$A$2:$A$48,('Conciliacion de compuestos'!$D$2:$D$48="conciliado")*('Conciliacion de compuestos'!$E$2:$E$48="OK")*((('Conciliacion de compuestos'!$M$2:$M$48=A12)+('Conciliacion de compuestos'!$N$2:$N$48=A12)+('Conciliacion de compuestos'!$O$2:$O$48=A12))>0))),""),"") | G12: =IF(I12="conciliado","conciliado","por revisar") | I12: =IF(SUM(COUNTIFS('Conciliacion de compuestos'!$D$2:$D$48,"conciliado",'Conciliacion de compuestos'!$E$2:$E$48,"OK",'Conciliacion de compuestos'!$M$2:$M$48,A12),COUNTIFS('Conciliacion de compuestos'!$D$2:$D$48,"conciliado",'Conciliacion de compuestos'!$E$2:$E$48,"OK",'Conciliacion de compuestos'!$N$2:$N$48,A12),COUNTIFS('Conciliacion de compuestos'!$D$2:$D$48,"conciliado",'Conciliacion de compuestos'!$E$2:$E$48,"OK",'Conciliacion de compuestos'!$O$2:$O$48,A12))>0,"conciliado","por revisar")
A13: 7 | B13: 45992 | C13: ca caicedo jimenez | D13: 62000 | E13: =IF(G13="conciliado","conciliado",I13) | F13: =IF(SUM(COUNTIFS('Conciliacion de compuestos'!$D$2:$D$48,"conciliado",'Conciliacion de compuestos'!$E$2:$E$48,"OK",'Conciliacion de compuestos'!$M$2:$M$48,A13),COUNTIFS('Conciliacion de compuestos'!$D$2:$D$48,"conciliado",'Conciliacion de compuestos'!$E$2:$E$48,"OK",'Conciliacion de compuestos'!$N$2:$N$48,A13),COUNTIFS('Conciliacion de compuestos'!$D$2:$D$48,"conciliado",'Conciliacion de compuestos'!$E$2:$E$48,"OK",'Conciliacion de compuestos'!$O$2:$O$48,A13))>0,IFERROR(TEXTJOIN(CHAR(10),TRUE,FILTER('Conciliacion de compuestos'!$A$2:$A$48,('Conciliacion de compuestos'!$D$2:$D$48="conciliado")*('Conciliacion de compuestos'!$E$2:$E$48="OK")*((('Conciliacion de compuestos'!$M$2:$M$48=A13)+('Conciliacion de compuestos'!$N$2:$N$48=A13)+('Conciliacion de compuestos'!$O$2:$O$48=A13))>0))),""),"") | G13: =IF(I13="conciliado","conciliado","por revisar") | I13: =IF(SUM(COUNTIFS('Conciliacion de compuestos'!$D$2:$D$48,"conciliado",'Conciliacion de compuestos'!$E$2:$E$48,"OK",'Conciliacion de compuestos'!$M$2:$M$48,A13),COUNTIFS('Conciliacion de compuestos'!$D$2:$D$48,"conciliado",'Conciliacion de compuestos'!$E$2:$E$48,"OK",'Conciliacion de compuestos'!$N$2:$N$48,A13),COUNTIFS('Conciliacion de compuestos'!$D$2:$D$48,"conciliado",'Conciliacion de compuestos'!$E$2:$E$48,"OK",'Conciliacion de compuestos'!$O$2:$O$48,A13))>0,"conciliado","por revisar")
A14: 2 | B14: 45992 | C14: gomez jimenez judith | D14: 44880 | E14: =IF(G14="conciliado","conciliado",I14) | F14: =IF(SUM(COUNTIFS('Conciliacion de compuestos'!$D$2:$D$48,"conciliado",'Conciliacion de compuestos'!$E$2:$E$48,"OK",'Conciliacion de compuestos'!$M$2:$M$48,A14),COUNTIFS('Conciliacion de compuestos'!$D$2:$D$48,"conciliado",'Conciliacion de compuestos'!$E$2:$E$48,"OK",'Conciliacion de compuestos'!$N$2:$N$48,A14),COUNTIFS('Conciliacion de compuestos'!$D$2:$D$48,"conciliado",'Conciliacion de compuestos'!$E$2:$E$48,"OK",'Conciliacion de compuestos'!$O$2:$O$48,A14))>0,IFERROR(TEXTJOIN(CHAR(10),TRUE,FILTER('Conciliacion de compuestos'!$A$2:$A$48,('Conciliacion de compuestos'!$D$2:$D$48="conciliado")*('Conciliacion de compuestos'!$E$2:$E$48="OK")*((('Conciliacion de compuestos'!$M$2:$M$48=A14)+('Conciliacion de compuestos'!$N$2:$N$48=A14)+('Conciliacion de compuestos'!$O$2:$O$48=A14))>0))),""),"") | G14: =IF(I14="conciliado","conciliado","por revisar") | I14: =IF(SUM(COUNTIFS('Conciliacion de compuestos'!$D$2:$D$48,"conciliado",'Conciliacion de compuestos'!$E$2:$E$48,"OK",'Conciliacion de compuestos'!$M$2:$M$48,A14),COUNTIFS('Conciliacion de compuestos'!$D$2:$D$48,"conciliado",'Conciliacion de compuestos'!$E$2:$E$48,"OK",'Conciliacion de compuestos'!$N$2:$N$48,A14),COUNTIFS('Conciliacion de compuestos'!$D$2:$D$48,"conciliado",'Conciliacion de compuestos'!$E$2:$E$48,"OK",'Conciliacion de compuestos'!$O$2:$O$48,A14))>0,"conciliado","por revisar")
A15: 3 | B15: 45992 | C15: buelvas diaz jose mi | D15: 68800 | E15: =IF(G15="conciliado","conciliado",I15) | F15: =IF(SUM(COUNTIFS('Conciliacion de compuestos'!$D$2:$D$48,"conciliado",'Conciliacion de compuestos'!$E$2:$E$48,"OK",'Conciliacion de compuestos'!$M$2:$M$48,A15),COUNTIFS('Conciliacion de compuestos'!$D$2:$D$48,"conciliado",'Conciliacion de compuestos'!$E$2:$E$48,"OK",'Conciliacion de compuestos'!$N$2:$N$48,A15),COUNTIFS('Conciliacion de compuestos'!$D$2:$D$48,"conciliado",'Conciliacion de compuestos'!$E$2:$E$48,"OK",'Conciliacion de compuestos'!$O$2:$O$48,A15))>0,IFERROR(TEXTJOIN(CHAR(10),TRUE,FILTER('Conciliacion de compuestos'!$A$2:$A$48,('Conciliacion de compuestos'!$D$2:$D$48="conciliado")*('Conciliacion de compuestos'!$E$2:$E$48="OK")*((('Conciliacion de compuestos'!$M$2:$M$48=A15)+('Conciliacion de compuestos'!$N$2:$N$48=A15)+('Conciliacion de compuestos'!$O$2:$O$48=A15))>0))),""),"") | G15: =IF(I15="conciliado","conciliado","por revisar") | I15: =IF(SUM(COUNTIFS('Conciliacion de compuestos'!$D$2:$D$48,"conciliado",'Conciliacion de compuestos'!$E$2:$E$48,"OK",'Conciliacion de compuestos'!$M$2:$M$48,A15),COUNTIFS('Conciliacion de compuestos'!$D$2:$D$48,"conciliado",'Conciliacion de compuestos'!$E$2:$E$48,"OK",'Conciliacion de compuestos'!$N$2:$N$48,A15),COUNTIFS('Conciliacion de compuestos'!$D$2:$D$48,"conciliado",'Conciliacion de compuestos'!$E$2:$E$48,"OK",'Conciliacion de compuestos'!$O$2:$O$48,A15))>0,"conciliado","por revisar")
... A21: 9 | B21: 45993 | C21: acosta jaiber rosero | D21: 196000 | E21: =IF(G21="conciliado","conciliado",I21) | F21: =IF(SUM(COUNTIFS('Conciliacion de compuestos'!$D$2:$D$48,"conciliado",'Conciliacion de compuestos'!$E$2:$E$48,"OK",'Conciliacion de compuestos'!$M$2:$M$48,A21),COUNTIFS('Conciliacion de compuestos'!$D$2:$D$48,"conciliado",'Conciliacion de compuestos'!$E$2:$E$48,"OK",'Conciliacion de compuestos'!$N$2:$N$48,A21),COUNTIFS('Conciliacion de compuestos'!$D$2:$D$48,"conciliado",'Conciliacion de compuestos'!$E$2:$E$48,"OK",'Conciliacion de compuestos'!$O$2:$O$48,A21))>0,IFERROR(TEXTJOIN(CHAR(10),TRUE,FILTER('Conciliacion de compuestos'!$A$2:$A$48,('Conciliacion de compuestos'!$D$2:$D$48="conciliado")*('Conciliacion de compuestos'!$E$2:$E$48="OK")*((('Conciliacion de compuestos'!$M$2:$M$48=A21)+('Conciliacion de compuestos'!$N$2:$N$48=A21)+('Conciliacion de compuestos'!$O$2:$O$48=A21))>0))),""),"") | G21: =IF(I21="conciliado","conciliado","por revisar") | I21: =IF(SUM(COUNTIFS('Conciliacion de compuestos'!$D$2:$D$48,"conciliado",'Conciliacion de compuestos'!$E$2:$E$48,"OK",'Conciliacion de compuestos'!$M$2:$M$48,A21),COUNTIFS('Conciliacion de compuestos'!$D$2:$D$48,"conciliado",'Conciliacion de compuestos'!$E$2:$E$48,"OK",'Conciliacion de compuestos'!$N$2:$N$48,A21),COUNTIFS('Conciliacion de compuestos'!$D$2:$D$48,"conciliado",'Conciliacion de compuestos'!$E$2:$E$48,"OK",'Conciliacion de compuestos'!$O$2:$O$48,A21))>0,"conciliado","por revisar")
A22: 14 | B22: 45994 | C22: a altipal s s | D22: -1421972 | E22: =IF(G22="conciliado","conciliado",I22) | F22: 191 | 2025-12-03 | -1,421,972 | entre inte internet terceros transferencias | G22: =IF(I22="conciliado","conciliado","por revisar") | I22: conciliado
A23: 15 | B23: 45994 | C23: ltda neiva ventas | D23: -2357032 | E23: =IF(G23="conciliado","conciliado",I23) | F23: 193 | 2025-12-03 | -2,357,032 | entre inte internet terceros transferencias | G23: =IF(I23="conciliado","conciliado","por revisar") | I23: conciliado
A24: 17 | B24: 45994 | C24: jaramillo leid ramos | D24: 52800 | E24: =IF(G24="conciliado","conciliado",I24) | F24: =IF(SUM(COUNTIFS('Conciliacion de compuestos'!$D$2:$D$48,"conciliado",'Conciliacion de compuestos'!$E$2:$E$48,"OK",'Conciliacion de compuestos'!$M$2:$M$48,A24),COUNTIFS('Conciliacion de compuestos'!$D$2:$D$48,"conciliado",'Conciliacion de compuestos'!$E$2:$E$48,"OK",'Conciliacion de compuestos'!$N$2:$N$48,A24),COUNTIFS('Conciliacion de compuestos'!$D$2:$D$48,"conciliado",'Conciliacion de compuestos'!$E$2:$E$48,"OK",'Conciliacion de compuestos'!$O$2:$O$48,A24))>0,IFERROR(TEXTJOIN(CHAR(10),TRUE,FILTER('Conciliacion de compuestos'!$A$2:$A$48,('Conciliacion de compuestos'!$D$2:$D$48="conciliado")*('Conciliacion de compuestos'!$E$2:$E$48="OK")*((('Conciliacion de compuestos'!$M$2:$M$48=A24)+('Conciliacion de compuestos'!$N$2:$N$48=A24)+('Conciliacion de compuestos'!$O$2:$O$48=A24))>0))),""),"") | G24: =IF(I24="conciliado","conciliado","por revisar") | I24: =IF(SUM(COUNTIFS('Conciliacion de compuestos'!$D$2:$D$48,"conciliado",'Conciliacion de compuestos'!$E$2:$E$48,"OK",'Conciliacion de compuestos'!$M$2:$M$48,A24),COUNTIFS('Conciliacion de compuestos'!$D$2:$D$48,"conciliado",'Conciliacion de compuestos'!$E$2:$E$48,"OK",'Conciliacion de compuestos'!$N$2:$N$48,A24),COUNTIFS('Conciliacion de compuestos'!$D$2:$D$48,"conciliado",'Conciliacion de compuestos'!$E$2:$E$48,"OK",'Conciliacion de compuestos'!$O$2:$O$48,A24))>0,"conciliado","por revisar")
A25: 16 | B25: 45994 | C25: arteaga ayda m troya | D25: 38200 | E25: =IF(G25="conciliado","conciliado",I25) | F25: =IF(SUM(COUNTIFS('Conciliacion de compuestos'!$D$2:$D$48,"conciliado",'Conciliacion de compuestos'!$E$2:$E$48,"OK",'Conciliacion de compuestos'!$M$2:$M$48,A25),COUNTIFS('Conciliacion de compuestos'!$D$2:$D$48,"conciliado",'Conciliacion de compuestos'!$E$2:$E$48,"OK",'Conciliacion de compuestos'!$N$2:$N$48,A25),COUNTIFS('Conciliacion de compuestos'!$D$2:$D$48,"conciliado",'Conciliacion de compuestos'!$E$2:$E$48,"OK",'Conciliacion de compuestos'!$O$2:$O$48,A25))>0,IFERROR(TEXTJOIN(CHAR(10),TRUE,FILTER('Conciliacion de compuestos'!$A$2:$A$48,('Conciliacion de compuestos'!$D$2:$D$48="conciliado")*('Conciliacion de compuestos'!$E$2:$E$48="OK")*((('Conciliacion de compuestos'!$M$2:$M$48=A25)+('Conciliacion de compuestos'!$N$2:$N$48=A25)+('Conciliacion de compuestos'!$O$2:$O$48=A25))>0))),""),"") | G25: =IF(I25="conciliado","conciliado","por revisar") | I25: =IF(SUM(COUNTIFS('Conciliacion de compuestos'!$D$2:$D$48,"conciliado",'Conciliacion de compuestos'!$E$2:$E$48,"OK",'Conciliacion de compuestos'!$M$2:$M$48,A25),COUNTIFS('Conciliacion de compuestos'!$D$2:$D$48,"conciliado",'Conciliacion de compuestos'!$E$2:$E$48,"OK",'Conciliacion de compuestos'!$N$2:$N$48,A25),COUNTIFS('Conciliacion de compuestos'!$D$2:$D$48,"conciliado",'Conciliacion de compuestos'!$E$2:$E$48,"OK",'Conciliacion de compuestos'!$O$2:$O$48,A25))>0,"conciliado","por revisar")
A26: 20 | B26: 45994 | C26: al enriquez yaguapaz | D26: 23564 | E26: =IF(G26="conciliado","conciliado",I26) | F26: =IF(SUM(COUNTIFS('Conciliacion de compuestos'!$D$2:$D$48,"conciliado",'Conciliacion de compuestos'!$E$2:$E$48,"OK",'Conciliacion de compuestos'!$M$2:$M$48,A26),COUNTIFS('Conciliacion de compuestos'!$D$2:$D$48,"conciliado",'Conciliacion de compuestos'!$E$2:$E$48,"OK",'Conciliacion de compuestos'!$N$2:$N$48,A26),COUNTIFS('Conciliacion de compuestos'!$D$2:$D$48,"conciliado",'Conciliacion de compuestos'!$E$2:$E$48,"OK",'Conciliacion de compuestos'!$O$2:$O$48,A26))>0,IFERROR(TEXTJOIN(CHAR(10),TRUE,FILTER('Conciliacion de compuestos'!$A$2:$A$48,('Conciliacion de compuestos'!$D$2:$D$48="conciliado")*('Conciliacion de compuestos'!$E$2:$E$48="OK")*((('Conciliacion de compuestos'!$M$2:$M$48=A26)+('Conciliacion de compuestos'!$N$2:$N$48=A26)+('Conciliacion de compuestos'!$O$2:$O$48=A26))>0))),""),"") | G26: =IF(I26="conciliado","conciliado","por revisar") | I26: =IF(SUM(COUNTIFS('Conciliacion de compuestos'!$D$2:$D$48,"conciliado",'Conciliacion de compuestos'!$E$2:$E$48,"OK",'Conciliacion de compuestos'!$M$2:$M$48,A26),COUNTIFS('Conciliacion de compuestos'!$D$2:$D$48,"conciliado",'Conciliacion de compuestos'!$E$2:$E$48,"OK",'Conciliacion de compuestos'!$N$2:$N$48,A26),COUNTIFS('Conciliacion de compuestos'!$D$2:$D$48,"conciliado",'Conciliacion de compuestos'!$E$2:$E$48,"OK",'Conciliacion de compuestos'!$O$2:$O$48,A26))>0,"conciliado","por revisar")
A27: 21 | B27: 45994 | C27: arteaga j jeins ruiz | D27: 20300 | E27: =IF(G27="conciliado","conciliado",I27) | F27: =IF(SUM(COUNTIFS('Conciliacion de compuestos'!$D$2:$D$48,"conciliado",'Conciliacion de compuestos'!$E$2:$E$48,"OK",'Conciliacion de compuestos'!$M$2:$M$48,A27),COUNTIFS('Conciliacion de compuestos'!$D$2:$D$48,"conciliado",'Conciliacion de compuestos'!$E$2:$E$48,"OK",'Conciliacion de compuestos'!$N$2:$N$48,A27),COUNTIFS('Conciliacion de compuestos'!$D$2:$D$48,"conciliado",'Conciliacion de compuestos'!$E$2:$E$48,"OK",'Conciliacion de compuestos'!$O$2:$O$48,A27))>0,IFERROR(TEXTJOIN(CHAR(10),TRUE,FILTER('Conciliacion de compuestos'!$A$2:$A$48,('Conciliacion de compuestos'!$D$2:$D$48="conciliado")*('Conciliacion de compuestos'!$E$2:$E$48="OK")*((('Conciliacion de compuestos'!$M$2:$M$48=A27)+('Conciliacion de compuestos'!$N$2:$N$48=A27)+('Conciliacion de compuestos'!$O$2:$O$48=A27))>0))),""),"") | G27: =IF(I27="conciliado","conciliado","por revisar") | I27: =IF(SUM(COUNTIFS('Conciliacion de compuestos'!$D$2:$D$48,"conciliado",'Conciliacion de compuestos'!$E$2:$E$48,"OK",'Conciliacion de compuestos'!$M$2:$M$48,A27),COUNTIFS('Conciliacion de compuestos'!$D$2:$D$48,"conciliado",'Conciliacion de compuestos'!$E$2:$E$48,"OK",'Conciliacion de compuestos'!$N$2:$N$48,A27),COUNTIFS('Conciliacion de compuestos'!$D$2:$D$48,"conciliado",'Conciliacion de compuestos'!$E$2:$E$48,"OK",'Conciliacion de compuestos'!$O$2:$O$48,A27))>0,"conciliado","por revisar")
A28: 23 | B28: 45995 | C28: del tolima ventas | D28: -3751132 | E28: =IF(G28="conciliado","conciliado",I28) | F28: 225 | 2025-12-04 | -3,751,132 | entre inte internet terceros transferencias | G28: =IF(I28="conciliado","conciliado","por revisar") | I28: conciliado
A29: 24 | B29: 45995 | C29: distrilineas sas ysc | D29: -4362465 | E29: =IF(G29="conciliado","conciliado",I29) | F29: 227 | 2025-12-04 | -4,362,465 | entre inte internet terceros transferencias | G29: =IF(I29="conciliado","conciliado","por revisar") | I29: conciliado
A30: 22 | B30: 45995 | C30: c d distribuciones s | D30: -4510389 | E30: =IF(G30="conciliado","conciliado",I30) | F30: 229 | 2025-12-04 | -4,510,389 | entre inte internet terceros transferencias | G30: =IF(I30="conciliado","conciliado","por revisar") | I30: conciliado
A31: 27 | B31: 45995 | C31: castillo fre velazco | D31: 27500 | E31: =IF(G31="conciliado","conciliado",I31) | F31: =IF(SUM(COUNTIFS('Conciliacion de compuestos'!$D$2:$D$48,"conciliado",'Conciliacion de compuestos'!$E$2:$E$48,"OK",'Conciliacion de compuestos'!$M$2:$M$48,A31),COUNTIFS('Conciliacion de compuestos'!$D$2:$D$48,"conciliado",'Conciliacion de compuestos'!$E$2:$E$48,"OK",'Conciliacion de compuestos'!$N$2:$N$48,A31),COUNTIFS('Conciliacion de compuestos'!$D$2:$D$48,"conciliado",'Conciliacion de compuestos'!$E$2:$E$48,"OK",'Conciliacion de compuestos'!$O$2:$O$48,A31))>0,IFERROR(TEXTJOIN(CHAR(10),TRUE,FILTER('Conciliacion de compuestos'!$A$2:$A$48,('Conciliacion de compuestos'!$D$2:$D$48="conciliado")*('Conciliacion de compuestos'!$E$2:$E$48="OK")*((('Conciliacion de compuestos'!$M$2:$M$48=A31)+('Conciliacion de compuestos'!$N$2:$N$48=A31)+('Conciliacion de compuestos'!$O$2:$O$48=A31))>0))),""),"") | G31: =IF(I31="conciliado","conciliado","por revisar") | I31: =IF(SUM(COUNTIFS('Conciliacion de compuestos'!$D$2:$D$48,"conciliado",'Conciliacion de compuestos'!$E$2:$E$48,"OK",'Conciliacion de compuestos'!$M$2:$M$48,A31),COUNTIFS('Conciliacion de compuestos'!$D$2:$D$48,"conciliado",'Conciliacion de compuestos'!$E$2:$E$48,"OK",'Conciliacion de compuestos'!$N$2:$N$48,A31),COUNTIFS('Conciliacion de compuestos'!$D$2:$D$48,"conciliado",'Conciliacion de compuestos'!$E$2:$E$48,"OK",'Conciliacion de compuestos'!$O$2:$O$48,A31))>0,"conciliado","por revisar")
A32: 26 | B32: 45995 | C32: eugen german vallejo | D32: 239000 | E32: =IF(G32="conciliado","conciliado",I32) | F32: =IF(SUM(COUNTIFS('Conciliacion de compuestos'!$D$2:$D$48,"conciliado",'Conciliacion de compuestos'!$E$2:$E$48,"OK",'Conciliacion de compuestos'!$M$2:$M$48,A32),COUNTIFS('Conciliacion de compuestos'!$D$2:$D$48,"conciliado",'Conciliacion de compuestos'!$E$2:$E$48,"OK",'Conciliacion de compuestos'!$N$2:$N$48,A32),COUNTIFS('Conciliacion de compuestos'!$D$2:$D$48,"conciliado",'Conciliacion de compuestos'!$E$2:$E$48,"OK",'Conciliacion de compuestos'!$O$2:$O$48,A32))>0,IFERROR(TEXTJOIN(CHAR(10),TRUE,FILTER('Conciliacion de compuestos'!$A$2:$A$48,('Conciliacion de compuestos'!$D$2:$D$48="conciliado")*('Conciliacion de compuestos'!$E$2:$E$48="OK")*((('Conciliacion de compuestos'!$M$2:$M$48=A32)+('Conciliacion de compuestos'!$N$2:$N$48=A32)+('Conciliacion de compuestos'!$O$2:$O$48=A32))>0))),""),"") | G32: =IF(I32="conciliado","conciliado","por revisar") | I32: =IF(SUM(COUNTIFS('Conciliacion de compuestos'!$D$2:$D$48,"conciliado",'Conciliacion de compuestos'!$E$2:$E$48,"OK",'Conciliacion de compuestos'!$M$2:$M$48,A32),COUNTIFS('Conciliacion de compuestos'!$D$2:$D$48,"conciliado",'Conciliacion de compuestos'!$E$2:$E$48,"OK",'Conciliacion de compuestos'!$N$2:$N$48,A32),COUNTIFS('Conciliacion de compuestos'!$D$2:$D$48,"conciliado",'Conciliacion de compuestos'!$E$2:$E$48,"OK",'Conciliacion de compuestos'!$O$2:$O$48,A32))>0,"conciliado","por revisar")
A33: 28 | B33: 45995 | C33: al enriquez yaguapaz | D33: 35900 | E33: =IF(G33="conciliado","conciliado",I33) | F33: =IF(SUM(COUNTIFS('Conciliacion de compuestos'!$D$2:$D$48,"conciliado",'Conciliacion de compuestos'!$E$2:$E$48,"OK",'Conciliacion de compuestos'!$M$2:$M$48,A33),COUNTIFS('Conciliacion de compuestos'!$D$2:$D$48,"conciliado",'Conciliacion de compuestos'!$E$2:$E$48,"OK",'Conciliacion de compuestos'!$N$2:$N$48,A33),COUNTIFS('Conciliacion de compuestos'!$D$2:$D$48,"conciliado",'Conciliacion de compuestos'!$E$2:$E$48,"OK",'Conciliacion de compuestos'!$O$2:$O$48,A33))>0,IFERROR(TEXTJOIN(CHAR(10),TRUE,FILTER('Conciliacion de compuestos'!$A$2:$A$48,('Conciliacion de compuestos'!$D$2:$D$48="conciliado")*('Conciliacion de compuestos'!$E$2:$E$48="OK")*((('Conciliacion de compuestos'!$M$2:$M$48=A33)+('Conciliacion de compuestos'!$N$2:$N$48=A33)+('Conciliacion de compuestos'!$O$2:$O$48=A33))>0))),""),"") | G33: =IF(I33="conciliado","conciliado","por revisar") | I33: =IF(SUM(COUNTIFS('Conciliacion de compuestos'!$D$2:$D$48,"conciliado",'Conciliacion de compuestos'!$E$2:$E$48,"OK",'Conciliacion de compuestos'!$M$2:$M$48,A33),COUNTIFS('Conciliacion de compuestos'!$D$2:$D$48,"conciliado",'Conciliacion de compuestos'!$E$2:$E$48,"OK",'Conciliacion de compuestos'!$N$2:$N$48,A33),COUNTIFS('Conciliacion de compuestos'!$D$2:$D$48,"conciliado",'Conciliacion de compuestos'!$E$2:$E$48,"OK",'Conciliacion de compuestos'!$O$2:$O$48,A33))>0,"conciliado","por revisar")
A34: 29 | B34: 45995 | C34: aldana joha renteria | D34: 36000 | E34: =IF(G34="conciliado","conciliado",I34) | F34: =IF(SUM(COUNTIFS('Conciliacion de compuestos'!$D$2:$D$48,"conciliado",'Conciliacion de compuestos'!$E$2:$E$48,"OK",'Conciliacion de compuestos'!$M$2:$M$48,A34),COUNTIFS('Conciliacion de compuestos'!$D$2:$D$48,"conciliado",'Conciliacion de compuestos'!$E$2:$E$48,"OK",'Conciliacion de compuestos'!$N$2:$N$48,A34),COUNTIFS('Conciliacion de compuestos'!$D$2:$D$48,"conciliado",'Conciliacion de compuestos'!$E$2:$E$48,"OK",'Conciliacion de compuestos'!$O$2:$O$48,A34))>0,IFERROR(TEXTJOIN(CHAR(10),TRUE,FILTER('Conciliacion de compuestos'!$A$2:$A$48,('Conciliacion de compuestos'!$D$2:$D$48="conciliado")*('Conciliacion de compuestos'!$E$2:$E$48="OK")*((('Conciliacion de compuestos'!$M$2:$M$48=A34)+('Conciliacion de compuestos'!$N$2:$N$48=A34)+('Conciliacion de compuestos'!$O$2:$O$48=A34))>0))),""),"") | G34: =IF(I34="conciliado","conciliado","por revisar") | I34: =IF(SUM(COUNTIFS('Conciliacion de compuestos'!$D$2:$D$48,"conciliado",'Conciliacion de compuestos'!$E$2:$E$48,"OK",'Conciliacion de compuestos'!$M$2:$M$48,A34),COUNTIFS('Conciliacion de compuestos'!$D$2:$D$48,"conciliado",'Conciliacion de compuestos'!$E$2:$E$48,"OK",'Conciliacion de compuestos'!$N$2:$N$48,A34),COUNTIFS('Conciliacion de compuestos'!$D$2:$D$48,"conciliado",'Conciliacion de compuestos'!$E$2:$E$48,"OK",'Conciliacion de compuestos'!$O$2:$O$48,A34))>0,"conciliado","por revisar")
A35: 25 | B35: 45995 | C35: ceron fre gomez john | D35: 92500 | E35: =IF(G35="conciliado","conciliado",I35) | F35: =IF(SUM(COUNTIFS('Conciliacion de compuestos'!$D$2:$D$48,"conciliado",'Conciliacion de compuestos'!$E$2:$E$48,"OK",'Conciliacion de compuestos'!$M$2:$M$48,A35),COUNTIFS('Conciliacion de compuestos'!$D$2:$D$48,"conciliado",'Conciliacion de compuestos'!$E$2:$E$48,"OK",'Conciliacion de compuestos'!$N$2:$N$48,A35),COUNTIFS('Conciliacion de compuestos'!$D$2:$D$48,"conciliado",'Conciliacion de compuestos'!$E$2:$E$48,"OK",'Conciliacion de compuestos'!$O$2:$O$48,A35))>0,IFERROR(TEXTJOIN(CHAR(10),TRUE,FILTER('Conciliacion de compuestos'!$A$2:$A$48,('Conciliacion de compuestos'!$D$2:$D$48="conciliado")*('Conciliacion de compuestos'!$E$2:$E$48="OK")*((('Conciliacion de compuestos'!$M$2:$M$48=A35)+('Conciliacion de compuestos'!$N$2:$N$48=A35)+('Conciliacion de compuestos'!$O$2:$O$48=A35))>0))),""),"") | G35: =IF(I35="conciliado","conciliado","por revisar") | I35: =IF(SUM(COUNTIFS('Conciliacion de compuestos'!$D$2:$D$48,"conciliado",'Conciliacion de compuestos'!$E$2:$E$48,"OK",'Conciliacion de compuestos'!$M$2:$M$48,A35),COUNTIFS('Conciliacion de compuestos'!$D$2:$D$48,"conciliado",'Conciliacion de compuestos'!$E$2:$E$48,"OK",'Conciliacion de compuestos'!$N$2:$N$48,A35),COUNTIFS('Conciliacion de compuestos'!$D$2:$D$48,"conciliado",'Conciliacion de compuestos'!$E$2:$E$48,"OK",'Conciliacion de compuestos'!$O$2:$O$48,A35))>0,"conciliado","por revisar")
A36: 79 | B36: 45999 | C36: garcia ma montenegro | D36: 65600 | E36: =IF(G36="conciliado","conciliado",I36) | F36: =IF(SUM(COUNTIFS('Conciliacion de compuestos'!$D$2:$D$48,"conciliado",'Conciliacion de compuestos'!$E$2:$E$48,"OK",'Conciliacion de compuestos'!$M$2:$M$48,A36),COUNTIFS('Conciliacion de compuestos'!$D$2:$D$48,"conciliado",'Conciliacion de compuestos'!$E$2:$E$48,"OK",'Conciliacion de compuestos'!$N$2:$N$48,A36),COUNTIFS('Conciliacion de compuestos'!$D$2:$D$48,"conciliado",'Conciliacion de compuestos'!$E$2:$E$48,"OK",'Conciliacion de compuestos'!$O$2:$O$48,A36))>0,IFERROR(TEXTJOIN(CHAR(10),TRUE,FILTER('Conciliacion de compuestos'!$A$2:$A$48,('Conciliacion de compuestos'!$D$2:$D$48="conciliado")*('Conciliacion de compuestos'!$E$2:$E$48="OK")*((('Conciliacion de compuestos'!$M$2:$M$48=A36)+('Conciliacion de compuestos'!$N$2:$N$48=A36)+('Conciliacion de compuestos'!$O$2:$O$48=A36))>0))),""),"") | G36: =IF(I36="conciliado","conciliado","por revisar") | I36: =IF(SUM(COUNTIFS('Conciliacion de compuestos'!$D$2:$D$48,"conciliado",'Conciliacion de compuestos'!$E$2:$E$48,"OK",'Conciliacion de compuestos'!$M$2:$M$48,A36),COUNTIFS('Conciliacion de compuestos'!$D$2:$D$48,"conciliado",'Conciliacion de compuestos'!$E$2:$E$48,"OK",'Conciliacion de compuestos'!$N$2:$N$48,A36),COUNTIFS('Conciliacion de compuestos'!$D$2:$D$48,"conciliado",'Conciliacion de compuestos'!$E$2:$E$48,"OK",'Conciliacion de compuestos'!$O$2:$O$48,A36))>0,"conciliado","por revisar")
A37: 82 | B37: 45999 | C37: nequirucama yagarin | D37: 60700 | E37: =IF(G37="conciliado","conciliado",I37) | F37: =IF(SUM(COUNTIFS('Conciliacion de compuestos'!$D$2:$D$48,"conciliado",'Conciliacion de compuestos'!$E$2:$E$48,"OK",'Conciliacion de compuestos'!$M$2:$M$48,A37),COUNTIFS('Conciliacion de compuestos'!$D$2:$D$48,"conciliado",'Conciliacion de compuestos'!$E$2:$E$48,"OK",'Conciliacion de compuestos'!$N$2:$N$48,A37),COUNTIFS('Conciliacion de compuestos'!$D$2:$D$48,"conciliado",'Conciliacion de compuestos'!$E$2:$E$48,"OK",'Conciliacion de compuestos'!$O$2:$O$48,A37))>0,IFERROR(TEXTJOIN(CHAR(10),TRUE,FILTER('Conciliacion de compuestos'!$A$2:$A$48,('Conciliacion de compuestos'!$D$2:$D$48="conciliado")*('Conciliacion de compuestos'!$E$2:$E$48="OK")*((('Conciliacion de compuestos'!$M$2:$M$48=A37)+('Conciliacion de compuestos'!$N$2:$N$48=A37)+('Conciliacion de compuestos'!$O$2:$O$48=A37))>0))),""),"") | G37: =IF(I37="conciliado","conciliado","por revisar") | I37: =IF(SUM(COUNTIFS('Conciliacion de compuestos'!$D$2:$D$48,"conciliado",'Conciliacion de compuestos'!$E$2:$E$48,"OK",'Conciliacion de compuestos'!$M$2:$M$48,A37),COUNTIFS('Conciliacion de compuestos'!$D$2:$D$48,"conciliado",'Conciliacion de compuestos'!$E$2:$E$48,"OK",'Conciliacion de compuestos'!$N$2:$N$48,A37),COUNTIFS('Conciliacion de compuestos'!$D$2:$D$48,"conciliado",'Conciliacion de compuestos'!$E$2:$E$48,"OK",'Conciliacion de compuestos'!$O$2:$O$48,A37))>0,"conciliado","por revisar")
A38: 76 | B38: 45999 | C38: benavides lopez sixt | D38: 151800 | E38: =IF(G38="conciliado","conciliado",I38) | F38: =IF(SUM(COUNTIFS('Conciliacion de compuestos'!$D$2:$D$48,"conciliado",'Conciliacion de compuestos'!$E$2:$E$48,"OK",'Conciliacion de compuestos'!$M$2:$M$48,A38),COUNTIFS('Conciliacion de compuestos'!$D$2:$D$48,"conciliado",'Conciliacion de compuestos'!$E$2:$E$48,"OK",'Conciliacion de compuestos'!$N$2:$N$48,A38),COUNTIFS('Conciliacion de compuestos'!$D$2:$D$48,"conciliado",'Conciliacion de compuestos'!$E$2:$E$48,"OK",'Conciliacion de compuestos'!$O$2:$O$48,A38))>0,IFERROR(TEXTJOIN(CHAR(10),TRUE,FILTER('Conciliacion de compuestos'!$A$2:$A$48,('Conciliacion de compuestos'!$D$2:$D$48="conciliado")*('Conciliacion de compuestos'!$E$2:$E$48="OK")*((('Conciliacion de compuestos'!$M$2:$M$48=A38)+('Conciliacion de compuestos'!$N$2:$N$48=A38)+('Conciliacion de compuestos'!$O$2:$O$48=A38))>0))),""),"") | G38: =IF(I38="conciliado","conciliado","por revisar") | I38: =IF(SUM(COUNTIFS('Conciliacion de compuestos'!$D$2:$D$48,"conciliado",'Conciliacion de compuestos'!$E$2:$E$48,"OK",'Conciliacion de compuestos'!$M$2:$M$48,A38),COUNTIFS('Conciliacion de compuestos'!$D$2:$D$48,"conciliado",'Conciliacion de compuestos'!$E$2:$E$48,"OK",'Conciliacion de compuestos'!$N$2:$N$48,A38),COUNTIFS('Conciliacion de compuestos'!$D$2:$D$48,"conciliado",'Conciliacion de compuestos'!$E$2:$E$48,"OK",'Conciliacion de compuestos'!$O$2:$O$48,A38))>0,"conciliado","por revisar")
A39: 78 | B39: 45999 | C39: cabrera enar narvaez | D39: 28300 | E39: =IF(G39="conciliado","conciliado",I39) | F39: =IF(SUM(COUNTIFS('Conciliacion de compuestos'!$D$2:$D$48,"conciliado",'Conciliacion de compuestos'!$E$2:$E$48,"OK",'Conciliacion de compuestos'!$M$2:$M$48,A39),COUNTIFS('Conciliacion de compuestos'!$D$2:$D$48,"conciliado",'Conciliacion de compuestos'!$E$2:$E$48,"OK",'Conciliacion de compuestos'!$N$2:$N$48,A39),COUNTIFS('Conciliacion de compuestos'!$D$2:$D$48,"conciliado",'Conciliacion de compuestos'!$E$2:$E$48,"OK",'Conciliacion de compuestos'!$O$2:$O$48,A39))>0,IFERROR(TEXTJOIN(CHAR(10),TRUE,FILTER('Conciliacion de compuestos'!$A$2:$A$48,('Conciliacion de compuestos'!$D$2:$D$48="conciliado")*('Conciliacion de compuestos'!$E$2:$E$48="OK")*((('Conciliacion de compuestos'!$M$2:$M$48=A39)+('Conciliacion de compuestos'!$N$2:$N$48=A39)+('Conciliacion de compuestos'!$O$2:$O$48=A39))>0))),""),"") | G39: =IF(I39="conciliado","conciliado","por revisar") | I39: =IF(SUM(COUNTIFS('Conciliacion de compuestos'!$D$2:$D$48,"conciliado",'Conciliacion de compuestos'!$E$2:$E$48,"OK",'Conciliacion de compuestos'!$M$2:$M$48,A39),COUNTIFS('Conciliacion de compuestos'!$D$2:$D$48,"conciliado",'Conciliacion de compuestos'!$E$2:$E$48,"OK",'Conciliacion de compuestos'!$N$2:$N$48,A39),COUNTIFS('Conciliacion de compuestos'!$D$2:$D$48,"conciliado",'Conciliacion de compuestos'!$E$2:$E$48,"OK",'Conciliacion de compuestos'!$O$2:$O$48,A39))>0,"conciliado","por revisar")
A40: 68 | B40: 45999 | C40: arias diego valencia | D40: 67800 | E40: =IF(G40="conciliado","conciliado",I40) | F40: =IF(SUM(COUNTIFS('Conciliacion de compuestos'!$D$2:$D$48,"conciliado",'Conciliacion de compuestos'!$E$2:$E$48,"OK",'Conciliacion de compuestos'!$M$2:$M$48,A40),COUNTIFS('Conciliacion de compuestos'!$D$2:$D$48,"conciliado",'Conciliacion de compuestos'!$E$2:$E$48,"OK",'Conciliacion de compuestos'!$N$2:$N$48,A40),COUNTIFS('Conciliacion de compuestos'!$D$2:$D$48,"conciliado",'Conciliacion de compuestos'!$E$2:$E$48,"OK",'Conciliacion de compuestos'!$O$2:$O$48,A40))>0,IFERROR(TEXTJOIN(CHAR(10),TRUE,FILTER('Conciliacion de compuestos'!$A$2:$A$48,('Conciliacion de compuestos'!$D$2:$D$48="conciliado")*('Conciliacion de compuestos'!$E$2:$E$48="OK")*((('Conciliacion de compuestos'!$M$2:$M$48=A40)+('Conciliacion de compuestos'!$N$2:$N$48=A40)+('Conciliacion de compuestos'!$O$2:$O$48=A40))>0))),""),"") | G40: =IF(I40="conciliado","conciliado","por revisar") | I40: =IF(SUM(COUNTIFS('Conciliacion de compuestos'!$D$2:$D$48,"conciliado",'Conciliacion de compuestos'!$E$2:$E$48,"OK",'Conciliacion de compuestos'!$M$2:$M$48,A40),COUNTIFS('Conciliacion de compuestos'!$D$2:$D$48,"conciliado",'Conciliacion de compuestos'!$E$2:$E$48,"OK",'Conciliacion de compuestos'!$N$2:$N$48,A40),COUNTIFS('Conciliacion de compuestos'!$D$2:$D$48,"conciliado",'Conciliacion de compuestos'!$E$2:$E$48,"OK",'Conciliacion de compuestos'!$O$2:$O$48,A40))>0,"conciliado","por revisar")
A41: 70 | B41: 45999 | C41: arboleda arias leidy | D41: 43958 | E41: =IF(G41="conciliado","conciliado",I41) | F41: =IF(SUM(COUNTIFS('Conciliacion de compuestos'!$D$2:$D$48,"conciliado",'Conciliacion de compuestos'!$E$2:$E$48,"OK",'Conciliacion de compuestos'!$M$2:$M$48,A41),COUNTIFS('Conciliacion de compuestos'!$D$2:$D$48,"conciliado",'Conciliacion de compuestos'!$E$2:$E$48,"OK",'Conciliacion de compuestos'!$N$2:$N$48,A41),COUNTIFS('Conciliacion de compuestos'!$D$2:$D$48,"conciliado",'Conciliacion de compuestos'!$E$2:$E$48,"OK",'Conciliacion de compuestos'!$O$2:$O$48,A41))>0,IFERROR(TEXTJOIN(CHAR(10),TRUE,FILTER('Conciliacion de compuestos'!$A$2:$A$48,('Conciliacion de compuestos'!$D$2:$D$48="conciliado")*('Conciliacion de compuestos'!$E$2:$E$48="OK")*((('Conciliacion de compuestos'!$M$2:$M$48=A41)+('Conciliacion de compuestos'!$N$2:$N$48=A41)+('Conciliacion de compuestos'!$O$2:$O$48=A41))>0))),""),"") | G41: =IF(I41="conciliado","conciliado","por revisar") | I41: =IF(SUM(COUNTIFS('Conciliacion de compuestos'!$D$2:$D$48,"conciliado",'Conciliacion de compuestos'!$E$2:$E$48,"OK",'Conciliacion de compuestos'!$M$2:$M$48,A41),COUNTIFS('Conciliacion de compuestos'!$D$2:$D$48,"conciliado",'Conciliacion de compuestos'!$E$2:$E$48,"OK",'Conciliacion de compuestos'!$N$2:$N$48,A41),COUNTIFS('Conciliacion de compuestos'!$D$2:$D$48,"conciliado",'Conciliacion de compuestos'!$E$2:$E$48,"OK",'Conciliacion de compuestos'!$O$2:$O$48,A41))>0,"conciliado","por revisar")
A42: 72 | B42: 45999 | C42: fernan salazar silva | D42: 62750 | E42: =IF(G42="conciliado","conciliado",I42) | F42: =IF(SUM(COUNTIFS('Conciliacion de compuestos'!$D$2:$D$48,"conciliado",'Conciliacion de compuestos'!$E$2:$E$48,"OK",'Conciliacion de compuestos'!$M$2:$M$48,A42),COUNTIFS('Conciliacion de compuestos'!$D$2:$D$48,"conciliado",'Conciliacion de compuestos'!$E$2:$E$48,"OK",'Conciliacion de compuestos'!$N$2:$N$48,A42),COUNTIFS('Conciliacion de compuestos'!$D$2:$D$48,"conciliado",'Conciliacion de compuestos'!$E$2:$E$48,"OK",'Conciliacion de compuestos'!$O$2:$O$48,A42))>0,IFERROR(TEXTJOIN(CHAR(10),TRUE,FILTER('Conciliacion de compuestos'!$A$2:$A$48,('Conciliacion de compuestos'!$D$2:$D$48="conciliado")*('Conciliacion de compuestos'!$E$2:$E$48="OK")*((('Conciliacion de compuestos'!$M$2:$M$48=A42)+('Conciliacion de compuestos'!$N$2:$N$48=A42)+('Conciliacion de compuestos'!$O$2:$O$48=A42))>0))),""),"") | G42: =IF(I42="conciliado","conciliado","por revisar") | I42: =IF(SUM(COUNTIFS('Conciliacion de compuestos'!$D$2:$D$48,"conciliado",'Conciliacion de compuestos'!$E$2:$E$48,"OK",'Conciliacion de compuestos'!$M$2:$M$48,A42),COUNTIFS('Conciliacion de compuestos'!$D$2:$D$48,"conciliado",'Conciliacion de compuestos'!$E$2:$E$48,"OK",'Conciliacion de compuestos'!$N$2:$N$48,A42),COUNTIFS('Conciliacion de compuestos'!$D$2:$D$48,"conciliado",'Conciliacion de compuestos'!$E$2:$E$48,"OK",'Conciliacion de compuestos'!$O$2:$O$48,A42))>0,"conciliado","por revisar")
... A57: 43 | B57: 45997 | C57: chavez esmer urquijo | D57: 222700 | E57: =IF(G57="conciliado","conciliado",I57) | F57: =IF(SUM(COUNTIFS('Conciliacion de compuestos'!$D$2:$D$48,"conciliado",'Conciliacion de compuestos'!$E$2:$E$48,"OK",'Conciliacion de compuestos'!$M$2:$M$48,A57),COUNTIFS('Conciliacion de compuestos'!$D$2:$D$48,"conciliado",'Conciliacion de compuestos'!$E$2:$E$48,"OK",'Conciliacion de compuestos'!$N$2:$N$48,A57),COUNTIFS('Conciliacion de compuestos'!$D$2:$D$48,"conciliado",'Conciliacion de compuestos'!$E$2:$E$48,"OK",'Conciliacion de compuestos'!$O$2:$O$48,A57))>0,IFERROR(TEXTJOIN(CHAR(10),TRUE,FILTER('Conciliacion de compuestos'!$A$2:$A$48,('Conciliacion de compuestos'!$D$2:$D$48="conciliado")*('Conciliacion de compuestos'!$E$2:$E$48="OK")*((('Conciliacion de compuestos'!$M$2:$M$48=A57)+('Conciliacion de compuestos'!$N$2:$N$48=A57)+('Conciliacion de compuestos'!$O$2:$O$48=A57))>0))),""),"") | G57: =IF(I57="conciliado","conciliado","por revisar") | I57: =IF(SUM(COUNTIFS('Conciliacion de compuestos'!$D$2:$D$48,"conciliado",'Conciliacion de compuestos'!$E$2:$E$48,"OK",'Conciliacion de compuestos'!$M$2:$M$48,A57),COUNTIFS('Conciliacion de compuestos'!$D$2:$D$48,"conciliado",'Conciliacion de compuestos'!$E$2:$E$48,"OK",'Conciliacion de compuestos'!$N$2:$N$48,A57),COUNTIFS('Conciliacion de compuestos'!$D$2:$D$48,"conciliado",'Conciliacion de compuestos'!$E$2:$E$48,"OK",'Conciliacion de compuestos'!$O$2:$O$48,A57))>0,"conciliado","por revisar")
A58: 88 | B58: 46000 | C58: norvey pantoja | D58: 20000 | E58: =IF(G58="conciliado","conciliado",I58) | F58: 381 | 2025-12-09 | 20,000 | consignacion credibanco d e | G58: =IF(I58="conciliado","conciliado","por revisar") | I58: conciliado
A59: 42 | B59: 45997 | C59: a delgado diaz edith | D59: 39000 | E59: =IF(G59="conciliado","conciliado",I59) | F59: =IF(SUM(COUNTIFS('Conciliacion de compuestos'!$D$2:$D$48,"conciliado",'Conciliacion de compuestos'!$E$2:$E$48,"OK",'Conciliacion de compuestos'!$M$2:$M$48,A59),COUNTIFS('Conciliacion de compuestos'!$D$2:$D$48,"conciliado",'Conciliacion de compuestos'!$E$2:$E$48,"OK",'Conciliacion de compuestos'!$N$2:$N$48,A59),COUNTIFS('Conciliacion de compuestos'!$D$2:$D$48,"conciliado",'Conciliacion de compuestos'!$E$2:$E$48,"OK",'Conciliacion de compuestos'!$O$2:$O$48,A59))>0,IFERROR(TEXTJOIN(CHAR(10),TRUE,FILTER('Conciliacion de compuestos'!$A$2:$A$48,('Conciliacion de compuestos'!$D$2:$D$48="conciliado")*('Conciliacion de compuestos'!$E$2:$E$48="OK")*((('Conciliacion de compuestos'!$M$2:$M$48=A59)+('Conciliacion de compuestos'!$N$2:$N$48=A59)+('Conciliacion de compuestos'!$O$2:$O$48=A59))>0))),""),"") | G59: =IF(I59="conciliado","conciliado","por revisar") | I59: =IF(SUM(COUNTIFS('Conciliacion de compuestos'!$D$2:$D$48,"conciliado",'Conciliacion de compuestos'!$E$2:$E$48,"OK",'Conciliacion de compuestos'!$M$2:$M$48,A59),COUNTIFS('Conciliacion de compuestos'!$D$2:$D$48,"conciliado",'Conciliacion de compuestos'!$E$2:$E$48,"OK",'Conciliacion de compuestos'!$N$2:$N$48,A59),COUNTIFS('Conciliacion de compuestos'!$D$2:$D$48,"conciliado",'Conciliacion de compuestos'!$E$2:$E$48,"OK",'Conciliacion de compuestos'!$O$2:$O$48,A59))>0,"conciliado","por revisar")
...

Sheet Conciliacion de compuestos
A1: Movimientos banco | B1: Movimientos libro_aux | C1: Diferencia | D1: Estado | E1: Validacion | F1: Descripcion | G1: Observacion | H1: ids banco | I1: ids libro_aux | J1: id banco 1 | K1: id banco 2 | L1: id banco 3 | M1: id libro_aux 1 | N1: id libro_aux 2 | O1: id libro_aux 3
A2: 1943 | 2025-12-30 | -27,932 | compra internet nd por pse 1945 | 2025-12-30 | -1,094,362 | compra internet nd por pse 1947 | 2025-12-30 | -6,295,213 | compra internet nd por pse | B2: 351 | 2025-12-30 | -7,417,507 | d de empresa energia | C2: 0 | D2: por revisar | E2: =IF(D2<>"conciliado","Pendiente",IF(C2<>0,"ERROR: diferencia distinta de cero",IF(OR(AND(J2<>"",SUM(COUNTIFS($D$2:$D$48,"conciliado",$J$2:$J$48,J2),COUNTIFS($D$2:$D$48,"conciliado",$K$2:$K$48,J2),COUNTIFS($D$2:$D$48,"conciliado",$L$2:$L$48,J2))>1),AND(K2<>"",SUM(COUNTIFS($D$2:$D$48,"conciliado",$J$2:$J$48,K2),COUNTIFS($D$2:$D$48,"conciliado",$K$2:$K$48,K2),COUNTIFS($D$2:$D$48,"conciliado",$L$2:$L$48,K2))>1),AND(L2<>"",SUM(COUNTIFS($D$2:$D$48,"conciliado",$J$2:$J$48,L2),COUNTIFS($D$2:$D$48,"conciliado",$K$2:$K$48,L2),COUNTIFS($D$2:$D$48,"conciliado",$L$2:$L$48,L2))>1)),"ERROR: banco ya usado en otro compuesto conciliado",IF(OR(AND(M2<>"",SUM(COUNTIFS($D$2:$D$48,"conciliado",$M$2:$M$48,M2),COUNTIFS($D$2:$D$48,"conciliado",$N$2:$N$48,M2),COUNTIFS($D$2:$D$48,"conciliado",$O$2:$O$48,M2))>1),AND(N2<>"",SUM(COUNTIFS($D$2:$D$48,"conciliado",$M$2:$M$48,N2),COUNTIFS($D$2:$D$48,"conciliado",$N$2:$N$48,N2),COUNTIFS($D$2:$D$48,"conciliado",$O$2:$O$48,N2))>1),AND(O2<>"",SUM(COUNTIFS($D$2:$D$48,"conciliado",$M$2:$M$48,O2),COUNTIFS($D$2:$D$48,"conciliado",$N$2:$N$48,O2),COUNTIFS($D$2:$D$48,"conciliado",$O$2:$O$48,O2))>1)),"ERROR: libro_aux ya usado en otro compuesto conciliado","OK")))) | F2: Posible compuesto detectado por suma exacta en la misma fecha. Revisar antes de conciliar. | H2: 1943, 1945, 1947 | I2: 351 | J2: 1943 | K2: 1945 | L2: 1947 | M2: 351
A3: 1007 | 2025-12-18 | 58,400 | depositos electronicos masterca transaccion 1012 | 2025-12-18 | 29,400 | depositos electronicos masterca transaccion | B3: 183 | 2025-12-18 | 87,800 | luz ma manzano ortiz | C3: 0 | D3: por revisar | E3: =IF(D3<>"conciliado","Pendiente",IF(C3<>0,"ERROR: diferencia distinta de cero",IF(OR(AND(J3<>"",SUM(COUNTIFS($D$2:$D$48,"conciliado",$J$2:$J$48,J3),COUNTIFS($D$2:$D$48,"conciliado",$K$2:$K$48,J3),COUNTIFS($D$2:$D$48,"conciliado",$L$2:$L$48,J3))>1),AND(K3<>"",SUM(COUNTIFS($D$2:$D$48,"conciliado",$J$2:$J$48,K3),COUNTIFS($D$2:$D$48,"conciliado",$K$2:$K$48,K3),COUNTIFS($D$2:$D$48,"conciliado",$L$2:$L$48,K3))>1),AND(L3<>"",SUM(COUNTIFS($D$2:$D$48,"conciliado",$J$2:$J$48,L3),COUNTIFS($D$2:$D$48,"conciliado",$K$2:$K$48,L3),COUNTIFS($D$2:$D$48,"conciliado",$L$2:$L$48,L3))>1)),"ERROR: banco ya usado en otro compuesto conciliado",IF(OR(AND(M3<>"",SUM(COUNTIFS($D$2:$D$48,"conciliado",$M$2:$M$48,M3),COUNTIFS($D$2:$D$48,"conciliado",$N$2:$N$48,M3),COUNTIFS($D$2:$D$48,"conciliado",$O$2:$O$48,M3))>1),AND(N3<>"",SUM(COUNTIFS($D$2:$D$48,"conciliado",$M$2:$M$48,N3),COUNTIFS($D$2:$D$48,"conciliado",$N$2:$N$48,N3),COUNTIFS($D$2:$D$48,"conciliado",$O$2:$O$48,N3))>1),AND(O3<>"",SUM(COUNTIFS($D$2:$D$48,"conciliado",$M$2:$M$48,O3),COUNTIFS($D$2:$D$48,"conciliado",$N$2:$N$48,O3),COUNTIFS($D$2:$D$48,"conciliado",$O$2:$O$48,O3))>1)),"ERROR: libro_aux ya usado en otro compuesto conciliado","OK")))) | F3: Posible compuesto detectado por suma exacta en la misma fecha. Revisar antes de conciliar. | H3: 1007, 1012 | I3: 183 | J3: 1007 | K3: 1012 | M3: 183
A4: 1024 | 2025-12-19 | 87,800 | depositos electronicos masterca transaccion 1034 | 2025-12-19 | 99,400 | depositos electronicos masterca transaccion | B4: 193 | 2025-12-19 | 187,200 | bolanos paladines st | C4: 0 | D4: por revisar | E4: =IF(D4<>"conciliado","Pendiente",IF(C4<>0,"ERROR: diferencia distinta de cero",IF(OR(AND(J4<>"",SUM(COUNTIFS($D$2:$D$48,"conciliado",$J$2:$J$48,J4),COUNTIFS($D$2:$D$48,"conciliado",$K$2:$K$48,J4),COUNTIFS($D$2:$D$48,"conciliado",$L$2:$L$48,J4))>1),AND(K4<>"",SUM(COUNTIFS($D$2:$D$48,"conciliado",$J$2:$J$48,K4),COUNTIFS($D$2:$D$48,"conciliado",$K$2:$K$48,K4),COUNTIFS($D$2:$D$48,"conciliado",$L$2:$L$48,K4))>1),AND(L4<>"",SUM(COUNTIFS($D$2:$D$48,"conciliado",$J$2:$J$48,L4),COUNTIFS($D$2:$D$48,"conciliado",$K$2:$K$48,L4),COUNTIFS($D$2:$D$48,"conciliado",$L$2:$L$48,L4))>1)),"ERROR: banco ya usado en otro compuesto conciliado",IF(OR(AND(M4<>"",SUM(COUNTIFS($D$2:$D$48,"conciliado",$M$2:$M$48,M4),COUNTIFS($D$2:$D$48,"conciliado",$N$2:$N$48,M4),COUNTIFS($D$2:$D$48,"conciliado",$O$2:$O$48,M4))>1),AND(N4<>"",SUM(COUNTIFS($D$2:$D$48,"conciliado",$M$2:$M$48,N4),COUNTIFS($D$2:$D$48,"conciliado",$N$2:$N$48,N4),COUNTIFS($D$2:$D$48,"conciliado",$O$2:$O$48,N4))>1),AND(O4<>"",SUM(COUNTIFS($D$2:$D$48,"conciliado",$M$2:$M$48,O4),COUNTIFS($D$2:$D$48,"conciliado",$N$2:$N$48,O4),COUNTIFS($D$2:$D$48,"conciliado",$O$2:$O$48,O4))>1)),"ERROR: libro_aux ya usado en otro compuesto conciliado","OK")))) | F4: Posible compuesto detectado por suma exacta en la misma fecha. Revisar antes de conciliar. | H4: 1024, 1034 | I4: 193 | J4: 1024 | K4: 1034 | M4: 193
A5: 1851 | 2025-12-29 | 39,200 | depositos electronicos masterca transaccion 1861 | 2025-12-29 | 28,200 | depositos electronicos masterca transaccion | B5: 344 | 2025-12-29 | 67,400 | gina m moncayo ponce | C5: 0 | D5: por revisar | E5: =IF(D5<>"conciliado","Pendiente",IF(C5<>0,"ERROR: diferencia distinta de cero",IF(OR(AND(J5<>"",SUM(COUNTIFS($D$2:$D$48,"conciliado",$J$2:$J$48,J5),COUNTIFS($D$2:$D$48,"conciliado",$K$2:$K$48,J5),COUNTIFS($D$2:$D$48,"conciliado",$L$2:$L$48,J5))>1),AND(K5<>"",SUM(COUNTIFS($D$2:$D$48,"conciliado",$J$2:$J$48,K5),COUNTIFS($D$2:$D$48,"conciliado",$K$2:$K$48,K5),COUNTIFS($D$2:$D$48,"conciliado",$L$2:$L$48,K5))>1),AND(L5<>"",SUM(COUNTIFS($D$2:$D$48,"conciliado",$J$2:$J$48,L5),COUNTIFS($D$2:$D$48,"conciliado",$K$2:$K$48,L5),COUNTIFS($D$2:$D$48,"conciliado",$L$2:$L$48,L5))>1)),"ERROR: banco ya usado en otro compuesto conciliado",IF(OR(AND(M5<>"",SUM(COUNTIFS($D$2:$D$48,"conciliado",$M$2:$M$48,M5),COUNTIFS($D$2:$D$48,"conciliado",$N$2:$N$48,M5),COUNTIFS($D$2:$D$48,"conciliado",$O$2:$O$48,M5))>1),AND(N5<>"",SUM(COUNTIFS($D$2:$D$48,"conciliado",$M$2:$M$48,N5),COUNTIFS($D$2:$D$48,"conciliado",$N$2:$N$48,N5),COUNTIFS($D$2:$D$48,"conciliado",$O$2:$O$48,N5))>1),AND(O5<>"",SUM(COUNTIFS($D$2:$D$48,"conciliado",$M$2:$M$48,O5),COUNTIFS($D$2:$D$48,"conciliado",$N$2:$N$48,O5),COUNTIFS($D$2:$D$48,"conciliado",$O$2:$O$48,O5))>1)),"ERROR: libro_aux ya usado en otro compuesto conciliado","OK")))) | F5: Posible compuesto detectado por suma exacta en la misma fecha. Revisar antes de conciliar. | H5: 1851, 1861 | I5: 344 | J5: 1851 | K5: 1861 | M5: 344
A6: 26 | 2025-12-01 | 22,800 | consignacion credibanco d e 56 | 2025-12-01 | 22,400 | consignacion credibanco d e 106 | 2025-12-01 | 23,600 | consignacion credibanco d e | B6: 3 | 2025-12-01 | 68,800 | buelvas diaz jose mi | C6: 0 | D6: por revisar | E6: =IF(D6<>"conciliado","Pendiente",IF(C6<>0,"ERROR: diferencia distinta de cero",IF(OR(AND(J6<>"",SUM(COUNTIFS($D$2:$D$48,"conciliado",$J$2:$J$48,J6),COUNTIFS($D$2:$D$48,"conciliado",$K$2:$K$48,J6),COUNTIFS($D$2:$D$48,"conciliado",$L$2:$L$48,J6))>1),AND(K6<>"",SUM(COUNTIFS($D$2:$D$48,"conciliado",$J$2:$J$48,K6),COUNTIFS($D$2:$D$48,"conciliado",$K$2:$K$48,K6),COUNTIFS($D$2:$D$48,"conciliado",$L$2:$L$48,K6))>1),AND(L6<>"",SUM(COUNTIFS($D$2:$D$48,"conciliado",$J$2:$J$48,L6),COUNTIFS($D$2:$D$48,"conciliado",$K$2:$K$48,L6),COUNTIFS($D$2:$D$48,"conciliado",$L$2:$L$48,L6))>1)),"ERROR: banco ya usado en otro compuesto conciliado",IF(OR(AND(M6<>"",SUM(COUNTIFS($D$2:$D$48,"conciliado",$M$2:$M$48,M6),COUNTIFS($D$2:$D$48,"conciliado",$N$2:$N$48,M6),COUNTIFS($D$2:$D$48,"conciliado",$O$2:$O$48,M6))>1),AND(N6<>"",SUM(COUNTIFS($D$2:$D$48,"conciliado",$M$2:$M$48,N6),COUNTIFS($D$2:$D$48,"conciliado",$N$2:$N$48,N6),COUNTIFS($D$2:$D$48,"conciliado",$O$2:$O$48,N6))>1),AND(O6<>"",SUM(COUNTIFS($D$2:$D$48,"conciliado",$M$2:$M$48,O6),COUNTIFS($D$2:$D$48,"conciliado",$N$2:$N$48,O6),COUNTIFS($D$2:$D$48,"conciliado",$O$2:$O$48,O6))>1)),"ERROR: libro_aux ya usado en otro compuesto conciliado","OK")))) | F6: Posible compuesto detectado por suma exacta en la misma fecha. Revisar antes de conciliar. | H6: 26, 56, 106 | I6: 3 | J6: 26 | K6: 56 | L6: 106 | M6: 3
A7: 487 | 2025-12-09 | -888 | comision depositos electronicos mastercard 522 | 2025-12-09 | -722 | comision depositos electronicos mastercard 546 | 2025-12-09 | 28,500 | depositos electronicos masterca transaccion | B7: 84 | 2025-12-09 | 26,890 | elm piaguaje riascos | C7: 0 | D7: por revisar | E7: =IF(D7<>"conciliado","Pendiente",IF(C7<>0,"ERROR: diferencia distinta de cero",IF(OR(AND(J7<>"",SUM(COUNTIFS($D$2:$D$48,"conciliado",$J$2:$J$48,J7),COUNTIFS($D$2:$D$48,"conciliado",$K$2:$K$48,J7),COUNTIFS($D$2:$D$48,"conciliado",$L$2:$L$48,J7))>1),AND(K7<>"",SUM(COUNTIFS($D$2:$D$48,"conciliado",$J$2:$J$48,K7),COUNTIFS($D$2:$D$48,"conciliado",$K$2:$K$48,K7),COUNTIFS($D$2:$D$48,"conciliado",$L$2:$L$48,K7))>1),AND(L7<>"",SUM(COUNTIFS($D$2:$D$48,"conciliado",$J$2:$J$48,L7),COUNTIFS($D$2:$D$48,"conciliado",$K$2:$K$48,L7),COUNTIFS($D$2:$D$48,"conciliado",$L$2:$L$48,L7))>1)),"ERROR: banco ya usado en otro compuesto conciliado",IF(OR(AND(M7<>"",SUM(COUNTIFS($D$2:$D$48,"conciliado",$M$2:$M$48,M7),COUNTIFS($D$2:$D$48,"conciliado",$N$2:$N$48,M7),COUNTIFS($D$2:$D$48,"conciliado",$O$2:$O$48,M7))>1),AND(N7<>"",SUM(COUNTIFS($D$2:$D$48,"conciliado",$M$2:$M$48,N7),COUNTIFS($D$2:$D$48,"conciliado",$N$2:$N$48,N7),COUNTIFS($D$2:$D$48,"conciliado",$O$2:$O$48,N7))>1),AND(O7<>"",SUM(COUNTIFS($D$2:$D$48,"conciliado",$M$2:$M$48,O7),COUNTIFS($D$2:$D$48,"conciliado",$N$2:$N$48,O7),COUNTIFS($D$2:$D$48,"conciliado",$O$2:$O$48,O7))>1)),"ERROR: libro_aux ya usado en otro compuesto conciliado","OK")))) | F7: Posible compuesto detectado por suma exacta en la misma fecha. Revisar antes de conciliar. | H7: 487, 522, 546 | I7: 84 | J7: 487 | K7: 522 | L7: 546 | M7: 84
A8: 1099 | 2025-12-22 | 24,400 | consignacion credibanco d e 1209 | 2025-12-22 | 20,900 | consignacion credibanco d e 1219 | 2025-12-22 | 54,000 | consignacion credibanco d e | B8: 248 | 2025-12-22 | 99,300 | alexa garcia varela | C8: 0 | D8: por revisar | E8: =IF(D8<>"conciliado","Pendiente",IF(C8<>0,"ERROR: diferencia distinta de cero",IF(OR(AND(J8<>"",SUM(COUNTIFS($D$2:$D$48,"conciliado",$J$2:$J$48,J8),COUNTIFS($D$2:$D$48,"conciliado",$K$2:$K$48,J8),COUNTIFS($D$2:$D$48,"conciliado",$L$2:$L$48,J8))>1),AND(K8<>"",SUM(COUNTIFS($D$2:$D$48,"conciliado",$J$2:$J$48,K8),COUNTIFS($D$2:$D$48,"conciliado",$K$2:$K$48,K8),COUNTIFS($D$2:$D$48,"conciliado",$L$2:$L$48,K8))>1),AND(L8<>"",SUM(COUNTIFS($D$2:$D$48,"conciliado",$J$2:$J$48,L8),COUNTIFS($D$2:$D$48,"conciliado",$K$2:$K$48,L8),COUNTIFS($D$2:$D$48,"conciliado",$L$2:$L$48,L8))>1)),"ERROR: banco ya usado en otro compuesto conciliado",IF(OR(AND(M8<>"",SUM(COUNTIFS($D$2:$D$48,"conciliado",$M$2:$M$48,M8),COUNTIFS($D$2:$D$48,"conciliado",$N$2:$N$48,M8),COUNTIFS($D$2:$D$48,"conciliado",$O$2:$O$48,M8))>1),AND(N8<>"",SUM(COUNTIFS($D$2:$D$48,"conciliado",$M$2:$M$48,N8),COUNTIFS($D$2:$D$48,"conciliado",$N$2:$N$48,N8),COUNTIFS($D$2:$D$48,"conciliado",$O$2:$O$48,N8))>1),AND(O8<>"",SUM(COUNTIFS($D$2:$D$48,"conciliado",$M$2:$M$48,O8),COUNTIFS($D$2:$D$48,"conciliado",$N$2:$N$48,O8),COUNTIFS($D$2:$D$48,"conciliado",$O$2:$O$48,O8))>1)),"ERROR: libro_aux ya usado en otro compuesto conciliado","OK")))) | F8: Posible compuesto detectado por suma exacta en la misma fecha. Revisar antes de conciliar. | H8: 1099, 1209, 1219 | I8: 248 | J8: 1099 | K8: 1209 | L8: 1219 | M8: 248
