Workbook

Sheet Libro auxiliar vs banco
A1: Conciliacion Bancaria
A2: Libro Auxiliar | E2: Conciliacion Automatica | G2: Conciliacion manual
A3: ID | B3: Fecha | C3: Nombre | D3: Valor | E3: Estado | F3: Conciliado del banco con registros: | G3: Estado | H3: Conciliado del banco con registros: | I3: Estado automatico base
A4: 144 | B4: 46038 | C4: m mata nubia rosales | D4: 37700 | E4: =IF(G4="conciliado","conciliado",I4) | F4: =IF(SUM(COUNTIFS('Conciliacion de compuestos'!$D$2:$D$13,"conciliado",'Conciliacion de compuestos'!$E$2:$E$13,"OK",'Conciliacion de compuestos'!$M$2:$M$13,A4),COUNTIFS('Conciliacion de compuestos'!$D$2:$D$13,"conciliado",'Conciliacion de compuestos'!$E$2:$E$13,"OK",'Conciliacion de compuestos'!$N$2:$N$13,A4),COUNTIFS('Conciliacion de compuestos'!$D$2:$D$13,"conciliado",'Conciliacion de compuestos'!$E$2:$E$13,"OK",'Conciliacion de compuestos'!$O$2:$O$13,A4))>0,IFERROR(TEXTJOIN(CHAR(10),TRUE,FILTER('Conciliacion de compuestos'!$A$2:$A$13,('Conciliacion de compuestos'!$D$2:$D$13="conciliado")*('Conciliacion de compuestos'!$E$2:$E$13="OK")*((('Conciliacion de compuestos'!$M$2:$M$13=A4)+('Conciliacion de compuestos'!$N$2:$N$13=A4)+('Conciliacion de compuestos'!$O$2:$O$13=A4))>0))),""),"") | G4: =IF(I4="conciliado","conciliado","por revisar") | I4: =IF(SUM(COUNTIFS('Conciliacion de compuestos'!$D$2:$D$13,"conciliado",'Conciliacion de compuestos'!$E$2:$E$13,"OK",'Conciliacion de compuestos'!$M$2:$M$13,A4),COUNTIFS('Conciliacion de compuestos'!$D$2:$D$13,"conciliado",'Conciliacion de compuestos'!$E$2:$E$13,"OK",'Conciliacion de compuestos'!$N$2:$N$13,A4),COUNTIFS('Conciliacion de compuestos'!$D$2:$D$13,"conciliado",'Conciliacion de compuestos'!$E$2:$E$13,"OK",'Conciliacion de compuestos'!$O$2:$O$13,A4))>0,"conciliado","por revisar")
A5: 148 | B5: 46038 | C5: f luis moreno romero | D5: 22400 | E5: =IF(G5="conciliado","conciliado",I5) | F5: =IF(SUM(COUNTIFS('Conciliacion de compuestos'!$D$2:$D$13,"conciliado",'Conciliacion de compuestos'!$E$2:$E$13,"OK",'Conciliacion de compuestos'!$M$2:$M$13,A5),COUNTIFS('Conciliacion de compuestos'!$D$2:$D$13,"conciliado",'Conciliacion de compuestos'!$E$2:$E$13,"OK",'Conciliacion de compuestos'!$N$2:$N$13,A5),COUNTIFS('Conciliacion de compuestos'!$D$2:$D$13,"conciliado",'Conciliacion de compuestos'!$E$2:$E$13,"OK",'Conciliacion de compuestos'!$O$2:$O$13,A5))>0,IFERROR(TEXTJOIN(CHAR(10),TRUE,FILTER('Conciliacion de compuestos'!$A$2:$A$13,('Conciliacion de compuestos'!$D$2:$D$13="conciliado")*('Conciliacion de compuestos'!$E$2:$E$13="OK")*((('Conciliacion de compuestos'!$M$2:$M$13=A5)+('Conciliacion de compuestos'!$N$2:$N$13=A5)+('Conciliacion de compuestos'!$O$2:$O$13=A5))>0))),""),"") | G5: =IF(I5="conciliado","conciliado","por revisar") | I5: =IF(SUM(COUNTIFS('Conciliacion de compuestos'!$D$2:$D$13,"conciliado",'Conciliacion de compuestos'!$E$2:$E$13,"OK",'Conciliacion de compuestos'!$M$2:$M$13,A5),COUNTIFS('Conciliacion de compuestos'!$D$2:$D$13,"conciliado",'Conciliacion de compuestos'!$E$2:$E$13,"OK",'Conciliacion de compuestos'!$N$2:$N$13,A5),COUNTIFS('Conciliacion de compuestos'!$D$2:$D$13,"conciliado",'Conciliacion de compuestos'!$E$2:$E$13,"OK",'Conciliacion de compuestos'!$O$2:$O$13,A5))>0,"conciliado","por revisar")
A6: 100 | B6: 46032 | C6: hernandez jaid silva | D6: 50200 | E6: =IF(G6="conciliado","conciliado",I6) | F6: =IF(SUM(COUNTIFS('Conciliacion de compuestos'!$D$2:$D$13,"conciliado",'Conciliacion de compuestos'!$E$2:$E$13,"OK",'Conciliacion de compuestos'!$M$2:$M$13,A6),COUNTIFS('Conciliacion de compuestos'!$D$2:$D$13,"conciliado",'Conciliacion de compuestos'!$E$2:$E$13,"OK",'Conciliacion de compuestos'!$N$2:$N$13,A6),COUNTIFS('Conciliacion de compuestos'!$D$2:$D$13,"conciliado",'Conciliacion de compuestos'!$E$2:$E$13,"OK",'Conciliacion de compuestos'!$O$2:$O$13,A6))>0,IFERROR(TEXTJOIN(CHAR(10),TRUE,FILTER('Conciliacion de compuestos'!$A$2:$A$13,('Conciliacion de compuestos'!$D$2:$D$13="conciliado")*('Conciliacion de compuestos'!$E$2:$E$13="OK")*((('Conciliacion de compuestos'!$M$2:$M$13=A6)+('Conciliacion de compuestos'!$N$2:$N$13=A6)+('Conciliacion de compuestos'!$O$2:$O$13=A6))>0))),""),"") | G6: =IF(I6="conciliado","conciliado","por revisar") | I6: =IF(SUM(COUNTIFS('Conciliacion de compuestos'!$D$2:$D$13,"conciliado",'Conciliacion de compuestos'!$E$2:$E$13,"OK",'Conciliacion de compuestos'!$M$2:$M$13,A6),COUNTIFS('Conciliacion de compuestos'!$D$2:$D$13,"conciliado",'Conciliacion de compuestos'!$E$2:$E$13,"OK",'Conciliacion de compuestos'!$N$2:$N$13,A6),COUNTIFS('Conciliacion de compuestos'!$D$2:$D$13,"conciliado",'Conciliacion de compuestos'!$E$2:$E$13,"OK",'Conciliacion de compuestos'!$O$2:$O$13,A6))>0,"conciliado","por revisar")
A7: 180 | B7: 46042 | C7: dony norve pantoja | D7: 24800 | E7: =IF(G7="conciliado","conciliado",I7) | F7: =IF(SUM(COUNTIFS('Conciliacion de compuestos'!$D$2:$D$13,"conciliado",'Conciliacion de compuestos'!$E$2:$E$13,"OK",'Conciliacion de compuestos'!$M$2:$M$13,A7),COUNTIFS('Conciliacion de compuestos'!$D$2:$D$13,"conciliado",'Conciliacion de compuestos'!$E$2:$E$13,"OK",'Conciliacion de compuestos'!$N$2:$N$13,A7),COUNTIFS('Conciliacion de compuestos'!$D$2:$D$13,"conciliado",'Conciliacion de compuestos'!$E$2:$E$13,"OK",'Conciliacion de compuestos'!$O$2:$O$13,A7))>0,IFERROR(TEXTJOIN(CHAR(10),TRUE,FILTER('Conciliacion de compuestos'!$A$2:$A$13,('Conciliacion de compuestos'!$D$2:$D$13="conciliado")*('Conciliacion de compuestos'!$E$2:$E$13="OK")*((('Conciliacion de compuestos'!$M$2:$M$13=A7)+('Conciliacion de compuestos'!$N$2:$N$13=A7)+('Conciliacion de compuestos'!$O$2:$O$13=A7))>0))),""),"") | G7: =IF(I7="conciliado","conciliado","por revisar") | I7: =IF(SUM(COUNTIFS('Conciliacion de compuestos'!$D$2:$D$13,"conciliado",'Conciliacion de compuestos'!$E$2:$E$13,"OK",'Conciliacion de compuestos'!$M$2:$M$13,A7),COUNTIFS('Conciliacion de compuestos'!$D$2:$D$13,"conciliado",'Conciliacion de compuestos'!$E$2:$E$13,"OK",'Conciliacion de compuestos'!$N$2:$N$13,A7),COUNTIFS('Conciliacion de compuestos'!$D$2:$D$13,"conciliado",'Conciliacion de compuestos'!$E$2:$E$13,"OK",'Conciliacion de compuestos'!$O$2:$O$13,A7))>0,"conciliado","por revisar")
A8: 34 | B8: 46026 | C8: abela ortiz zambrano | D8: 69200 | E8: =IF(G8="conciliado","conciliado",I8) | F8: =IF(SUM(COUNTIFS('Conciliacion de compuestos'!$D$2:$D$13,"conciliado",'Conciliacion de compuestos'!$E$2:$E$13,"OK",'Conciliacion de compuestos'!$M$2:$M$13,A8),COUNTIFS('Conciliacion de compuestos'!$D$2:$D$13,"conciliado",'Conciliacion de compuestos'!$E$2:$E$13,"OK",'Conciliacion de compuestos'!$N$2:$N$13,A8),COUNTIFS('Conciliacion de compuestos'!$D$2:$D$13,"conciliado",'Conciliacion de compuestos'!$E$2:$E$13,"OK",'Conciliacion de compuestos'!$O$2:$O$13,A8))>0,IFERROR(TEXTJOIN(CHAR(10),TRUE,FILTER('Conciliacion de compuestos'!$A$2:$A$13,('Conciliacion de compuestos'!$D$2:$D$13="conciliado")*('Conciliacion de compuestos'!$E$2:$E$13="OK")*((('Conciliacion de compuestos'!$M$2:$M$13=A8)+('Conciliacion de compuestos'!$N$2:$N$13=A8)+('Conciliacion de compuestos'!$O$2:$O$13=A8))>0))),""),"") | G8: =IF(I8="conciliado","conciliado","por revisar") | I8: =IF(SUM(COUNTIFS('Conciliacion de compuestos'!$D$2:$D$13,"conciliado",'Conciliacion de compuestos'!$E$2:$E$13,"OK",'Conciliacion de compuestos'!$M$2:$M$13,A8),COUNTIFS('Conciliacion de compuestos'!$D$2:$D$13,"conciliado",'Conciliacion de compuestos'!$E$2:$E$13,"OK",'Conciliacion de compuestos'!$N$2:$N$13,A8),COUNTIFS('Conciliacion de compuestos'!$D$2:$D$13,"conciliado",'Conciliacion de compuestos'!$E$2:$E$13,"OK",'Conciliacion de compuestos'!$O$2:$O$13,A8))>0,"conciliado","por revisar")
A9: 27 | B9: 46026 | C9: fernan salazar silva | D9: 85500 | E9: =IF(G9="conciliado","conciliado",I9) | F9: =IF(SUM(COUNTIFS('Conciliacion de compuestos'!$D$2:$D$13,"conciliado",'Conciliacion de compuestos'!$E$2:$E$13,"OK",'Conciliacion de compuestos'!$M$2:$M$13,A9),COUNTIFS('Conciliacion de compuestos'!$D$2:$D$13,"conciliado",'Conciliacion de compuestos'!$E$2:$E$13,"OK",'Conciliacion de compuestos'!$N$2:$N$13,A9),COUNTIFS('Conciliacion de compuestos'!$D$2:$D$13,"conciliado",'Conciliacion de compuestos'!$E$2:$E$13,"OK",'Conciliacion de compuestos'!$O$2:$O$13,A9))>0,IFERROR(TEXTJOIN(CHAR(10),TRUE,FILTER('Conciliacion de compuestos'!$A$2:$A$13,('Conciliacion de compuestos'!$D$2:$D$13="conciliado")*('Conciliacion de compuestos'!$E$2:$E$13="OK")*((('Conciliacion de compuestos'!$M$2:$M$13=A9)+('Conciliacion de compuestos'!$N$2:$N$13=A9)+('Conciliacion de compuestos'!$O$2:$O$13=A9))>0))),""),"") | G9: =IF(I9="conciliado","conciliado","por revisar") | I9: =IF(SUM(COUNTIFS('Conciliacion de compuestos'!$D$2:$D$13,"conciliado",'Conciliacion de compuestos'!$E$2:$E$13,"OK",'Conciliacion de compuestos'!$M$2:$M$13,A9),COUNTIFS('Conciliacion de compuestos'!$D$2:$D$13,"conciliado",'Conciliacion de compuestos'!$E$2:$E$13,"OK",'Conciliacion de compuestos'!$N$2:$N$13,A9),COUNTIFS('Conciliacion de compuestos'!$D$2:$D$13,"conciliado",'Conciliacion de compuestos'!$E$2:$E$13,"OK",'Conciliacion de compuestos'!$O$2:$O$13,A9))>0,"conciliado","por revisar")
A10: 239 | B10: 46049 | C10: bastidas cordoba yol | D10: 60000 | E10: =IF(G10="conciliado","conciliado",I10) | F10: =IF(SUM(COUNTIFS('Conciliacion de compuestos'!$D$2:$D$13,"conciliado",'Conciliacion de compuestos'!$E$2:$E$13,"OK",'Conciliacion de compuestos'!$M$2:$M$13,A10),COUNTIFS('Conciliacion de compuestos'!$D$2:$D$13,"conciliado",'Conciliacion de compuestos'!$E$2:$E$13,"OK",'Conciliacion de compuestos'!$N$2:$N$13,A10),COUNTIFS('Conciliacion de compuestos'!$D$2:$D$13,"conciliado",'Conciliacion de compuestos'!$E$2:$E$13,"OK",'Conciliacion de compuestos'!$O$2:$O$13,A10))>0,IFERROR(TEXTJOIN(CHAR(10),TRUE,FILTER('Conciliacion de compuestos'!$A$2:$A$13,('Conciliacion de compuestos'!$D$2:$D$13="conciliado")*('Conciliacion de compuestos'!$E$2:$E$13="OK")*((('Conciliacion de compuestos'!$M$2:$M$13=A10)+('Conciliacion de compuestos'!$N$2:$N$13=A10)+('Conciliacion de compuestos'!$O$2:$O$13=A10))>0))),""),"") | G10: =IF(I10="conciliado","conciliado","por revisar") | I10: =IF(SUM(COUNTIFS('Conciliacion de compuestos'!$D$2:$D$13,"conciliado",'Conciliacion de compuestos'!$E$2:$E$13,"OK",'Conciliacion de compuestos'!$M$2:$M$13,A10),COUNTIFS('Conciliacion de compuestos'!$D$2:$D$13,"conciliado",'Conciliacion de compuestos'!$E$2:$E$13,"OK",'Conciliacion de compuestos'!$N$2:$N$13,A10),COUNTIFS('Conciliacion de compuestos'!$D$2:$D$13,"conciliado",'Conciliacion de compuestos'!$E$2:$E$13,"OK",'Conciliacion de compuestos'!$O$2:$O$13,A10))>0,"conciliado","por revisar")
A11: 31 | B11: 46026 | C11: alvarez mon quintero | D11: 226100 | E11: =IF(G11="conciliado","conciliado",I11) | F11: =IF(SUM(COUNTIFS('Conciliacion de compuestos'!$D$2:$D$13,"conciliado",'Conciliacion de compuestos'!$E$2:$E$13,"OK",'Conciliacion de compuestos'!$M$2:$M$13,A11),COUNTIFS('Conciliacion de compuestos'!$D$2:$D$13,"conciliado",'Conciliacion de compuestos'!$E$2:$E$13,"OK",'Conciliacion de compuestos'!$N$2:$N$13,A11),COUNTIFS('Conciliacion de compuestos'!$D$2:$D$13,"conciliado",'Conciliacion de compuestos'!$E$2:$E$13,"OK",'Conciliacion de compuestos'!$O$2:$O$13,A11))>0,IFERROR(TEXTJOIN(CHAR(10),TRUE,FILTER('Conciliacion de compuestos'!$A$2:$A$13,('Conciliacion de compuestos'!$D$2:$D$13="conciliado")*('Conciliacion de compuestos'!$E$2:$E$13="OK")*((('Conciliacion de compuestos'!$M$2:$M$13=A11)+('Conciliacion de compuestos'!$N$2:$N$13=A11)+('Conciliacion de compuestos'!$O$2:$O$13=A11))>0))),""),"") | G11: =IF(I11="conciliado","conciliado","por revisar") | I11: =IF(SUM(COUNTIFS('Conciliacion de compuestos'!$D$2:$D$13,"conciliado",'Conciliacion de compuestos'!$E$2:$E$13,"OK",'Conciliacion de compuestos'!$M$2:$M$13,A11),COUNTIFS('Conciliacion de compuestos'!$D$2:$D$13,"conciliado",'Conciliacion de compuestos'!$E$2:$E$13,"OK",'Conciliacion de compuestos'!$N$2:$N$13,A11),COUNTIFS('Conciliacion de compuestos'!$D$2:$D$13,"conciliado",'Conciliacion de compuestos'!$E$2:$E$13,"OK",'Conciliacion de compuestos'!$O$2:$O$13,A11))>0,"conciliado","por revisar")
A12: 36 | B12: 46026 | C12: hernadez valencia | D12: 84100 | E12: =IF(G12="conciliado","conciliado",I12) | F12: =IF(SUM(COUNTIFS('Conciliacion de compuestos'!$D$2:$D$13,"conciliado",'Conciliacion de compuestos'!$E$2:$E$13,"OK",'Conciliacion de compuestos'!$M$2:$M$13,A12),COUNTIFS('Conciliacion de compuestos'!$D$2:$D$13,"conciliado",'Conciliacion de compuestos'!$E$2:$E$13,"OK",'Conciliacion de compuestos'!$N$2:$N$13,A12),COUNTIFS('Conciliacion de compuestos'!$D$2:$D$13,"conciliado",'Conciliacion de compuestos'!$E$2:$E$13,"OK",'Conciliacion de compuestos'!$O$2:$O$13,A12))>0,IFERROR(TEXTJOIN(CHAR(10),TRUE,FILTER('Conciliacion de compuestos'!$A$2:$A$13,('Conciliacion de compuestos'!$D$2:$D$13="conciliado")*('Conciliacion de compuestos'!$E$2:$E$13="OK")*((('Conciliacion de compuestos'!$M$2:$M$13=A12)+('Conciliacion de compuestos'!$N$2:$N$13=A12)+('Conciliacion de compuestos'!$O$2:$O$13=A12))>0))),""),"") | G12: =IF(I12="conciliado","conciliado","por revisar") | I12: =IF(SUM(COUNTIFS('Conciliacion de compuestos'!$D$2:$D$13,"conciliado",'Conciliacion de compuestos'!$E$2:$E$13,"OK",'Conciliacion de compuestos'!$M$2:$M$13,A12),COUNTIFS('Conciliacion de compuestos'!$D$2:$D$13,"conciliado",'Conciliacion de compuestos'!$E$2:$E$13,"OK",'Conciliacion de compuestos'!$N$2:$N$13,A12),COUNTIFS('Conciliacion de compuestos'!$D$2:$D$13,"conciliado",'Conciliacion de compuestos'!$E$2:$E$13,"OK",'Conciliacion de compuestos'!$O$2:$O$13,A12))>0,"conciliado","por revisar")
A13: 32 | B13: 46026 | C13: coral jorge l rosero | D13: 42300 | E13: =IF(G13="conciliado","conciliado",I13) | F13: =IF(SUM(COUNTIFS('Conciliacion de compuestos'!$D$2:$D$13,"conciliado",'Conciliacion de compuestos'!$E$2:$E$13,"OK",'Conciliacion de compuestos'!$M$2:$M$13,A13),COUNTIFS('Conciliacion de compuestos'!$D$2:$D$13,"conciliado",'Conciliacion de compuestos'!$E$2:$E$13,"OK",'Conciliacion de compuestos'!$N$2:$N$13,A13),COUNTIFS('Conciliacion de compuestos'!$D$2:$D$13,"conciliado",'Conciliacion de compuestos'!$E$2:$E$13,"OK",'Conciliacion de compuestos'!$O$2:$O$13,A13))>0,IFERROR(TEXTJOIN(CHAR(10),TRUE,FILTER('Conciliacion de compuestos'!$A$2:$A$13,('Conciliacion de compuestos'!$D$2:$D$13="conciliado")*('Conciliacion de compuestos'!$E$2:$E$13="OK")*((('Conciliacion de compuestos'!$M$2:$M$13=A13)+('Conciliacion de compuestos'!$N$2:$N$13=A13)+('Conciliacion de compuestos'!$O$2:$O$13=A13))>0))),""),"") | G13: =IF(I13="conciliado","conciliado","por revisar") | I13: =IF(SUM(COUNTIFS('Conciliacion de compuestos'!$D$2:$D$13,"conciliado",'Conciliacion de compuestos'!$E$2:$E$13,"OK",'Conciliacion de compuestos'!$M$2:$M$13,A13),COUNTIFS('Conciliacion de compuestos'!$D$2:$D$13,"conciliado",'Conciliacion de compuestos'!$E$2:$E$13,"OK",'Conciliacion de compuestos'!$N$2:$N$13,A13),COUNTIFS('Conciliacion de compuestos'!$D$2:$D$13,"conciliado",'Conciliacion de compuestos'!$E$2:$E$13,"OK",'Conciliacion de compuestos'!$O$2:$O$13,A13))>0,"conciliado","por revisar")
A14: 10 | B14: 46024 | C14: cristian rosero | D14: 88000 | E14: =IF(G14="conciliado","conciliado",I14) | F14: =IF(SUM(COUNTIFS('Conciliacion de compuestos'!$D$2:$D$13,"conciliado",'Conciliacion de compuestos'!$E$2:$E$13,"OK",'Conciliacion de compuestos'!$M$2:$M$13,A14),COUNTIFS('Conciliacion de compuestos'!$D$2:$D$13,"conciliado",'Conciliacion de compuestos'!$E$2:$E$13,"OK",'Conciliacion de compuestos'!$N$2:$N$13,A14),COUNTIFS('Conciliacion de compuestos'!$D$2:$D$13,"conciliado",'Conciliacion de compuestos'!$E$2:$E$13,"OK",'Conciliacion de compuestos'!$O$2:$O$13,A14))>0,IFERROR(TEXTJOIN(CHAR(10),TRUE,FILTER('Conciliacion de compuestos'!$A$2:$A$13,('Conciliacion de compuestos'!$D$2:$D$13="conciliado")*('Conciliacion de compuestos'!$E$2:$E$13="OK")*((('Conciliacion de compuestos'!$M$2:$M$13=A14)+('Conciliacion de compuestos'!$N$2:$N$13=A14)+('Conciliacion de compuestos'!$O$2:$O$13=A14))>0))),""),"") | G14: =IF(I14="conciliado","conciliado","por revisar") | I14: =IF(SUM(COUNTIFS('Conciliacion de compuestos'!$D$2:$D$13,"conciliado",'Conciliacion de compuestos'!$E$2:$E$13,"OK",'Conciliacion de compuestos'!$M$2:$M$13,A14),COUNTIFS('Conciliacion de compuestos'!$D$2:$D$13,"conciliado",'Conciliacion de compuestos'!$E$2:$E$13,"OK",'Conciliacion de compuestos'!$N$2:$N$13,A14),COUNTIFS('Conciliacion de compuestos'!$D$2:$D$13,"conciliado",'Conciliacion de compuestos'!$E$2:$E$13,"OK",'Conciliacion de compuestos'!$O$2:$O$13,A14))>0,"conciliado","por revisar")
A15: 3 | B15: 46024 | C15: laso linsay pachucan | D15: 43200 | E15: =IF(G15="conciliado","conciliado",I15) | F15: =IF(SUM(COUNTIFS('Conciliacion de compuestos'!$D$2:$D$13,"conciliado",'Conciliacion de compuestos'!$E$2:$E$13,"OK",'Conciliacion de compuestos'!$M$2:$M$13,A15),COUNTIFS('Conciliacion de compuestos'!$D$2:$D$13,"conciliado",'Conciliacion de compuestos'!$E$2:$E$13,"OK",'Conciliacion de compuestos'!$N$2:$N$13,A15),COUNTIFS('Conciliacion de compuestos'!$D$2:$D$13,"conciliado",'Conciliacion de compuestos'!$E$2:$E$13,"OK",'Conciliacion de compuestos'!$O$2:$O$13,A15))>0,IFERROR(TEXTJOIN(CHAR(10),TRUE,FILTER('Conciliacion de compuestos'!$A$2:$A$13,('Conciliacion de compuestos'!$D$2:$D$13="conciliado")*('Conciliacion de compuestos'!$E$2:$E$13="OK")*((('Conciliacion de compuestos'!$M$2:$M$13=A15)+('Conciliacion de compuestos'!$N$2:$N$13=A15)+('Conciliacion de compuestos'!$O$2:$O$13=A15))>0))),""),"") | G15: =IF(I15="conciliado","conciliado","por revisar") | I15: =IF(SUM(COUNTIFS('Conciliacion de compuestos'!$D$2:$D$13,"conciliado",'Conciliacion de compuestos'!$E$2:$E$13,"OK",'Conciliacion de compuestos'!$M$2:$M$13,A15),COUNTIFS('Conciliacion de compuestos'!$D$2:$D$13,"conciliado",'Conciliacion de compuestos'!$E$2:$E$13,"OK",'Conciliacion de compuestos'!$N$2:$N$13,A15),COUNTIFS('Conciliacion de compuestos'!$D$2:$D$13,"conciliado",'Conciliacion de compuestos'!$E$2:$E$13,"OK",'Conciliacion de compuestos'!$O$2:$O$13,A15))>0,"conciliado","por revisar")
... A48: 55 | B48: 46028 | C48: lenin sousa tribaldo | D48: 96500 | E48: =IF(G48="conciliado","conciliado",I48) | F48: =IF(SUM(COUNTIFS('Conciliacion de compuestos'!$D$2:$D$13,"conciliado",'Conciliacion de compuestos'!$E$2:$E$13,"OK",'Conciliacion de compuestos'!$M$2:$M$13,A48),COUNTIFS('Conciliacion de compuestos'!$D$2:$D$13,"conciliado",'Conciliacion de compuestos'!$E$2:$E$13,"OK",'Conciliacion de compuestos'!$N$2:$N$13,A48),COUNTIFS('Conciliacion de compuestos'!$D$2:$D$13,"conciliado",'Conciliacion de compuestos'!$E$2:$E$13,"OK",'Conciliacion de compuestos'!$O$2:$O$13,A48))>0,IFERROR(TEXTJOIN(CHAR(10),TRUE,FILTER('Conciliacion de compuestos'!$A$2:$A$13,('Conciliacion de compuestos'!$D$2:$D$13="conciliado")*('Conciliacion de compuestos'!$E$2:$E$13="OK")*((('Conciliacion de compuestos'!$M$2:$M$13=A48)+('Conciliacion de compuestos'!$N$2:$N$13=A48)+('Conciliacion de compuestos'!$O$2:$O$13=A48))>0))),""),"") | G48: =IF(I48="conciliado","conciliado","por revisar") | I48: =IF(SUM(COUNTIFS('Conciliacion de compuestos'!$D$2:$D$13,"conciliado",'Conciliacion de compuestos'!$E$2:$E$13,"OK",'Conciliacion de compuestos'!$M$2:$M$13,A48),COUNTIFS('Conciliacion de compuestos'!$D$2:$D$13,"conciliado",'Conciliacion de compuestos'!$E$2:$E$13,"OK",'Conciliacion de compuestos'!$N$2:$N$13,A48),COUNTIFS('Conciliacion de compuestos'!$D$2:$D$13,"conciliado",'Conciliacion de compuestos'!$E$2:$E$13,"OK",'Conciliacion de compuestos'!$O$2:$O$13,A48))>0,"conciliado","por revisar")
A49: 80 | B49: 46030 | C49: lukumi mosquera | D49: 33200 | E49: =IF(G49="conciliado","conciliado",I49) | F49: 540 | 2026-01-08 | 33,200 | consignacion credibanco d e | G49: =IF(I49="conciliado","conciliado","por revisar") | I49: conciliado
A50: 62 | B50: 46029 | C50: giraldo luis medina | D50: 110300 | E50: =IF(G50="conciliado","conciliado",I50) | F50: =IF(SUM(COUNTIFS('Conciliacion de compuestos'!$D$2:$D$13,"conciliado",'Conciliacion de compuestos'!$E$2:$E$13,"OK",'Conciliacion de compuestos'!$M$2:$M$13,A50),COUNTIFS('Conciliacion de compuestos'!$D$2:$D$13,"conciliado",'Conciliacion de compuestos'!$E$2:$E$13,"OK",'Conciliacion de compuestos'!$N$2:$N$13,A50),COUNTIFS('Conciliacion de compuestos'!$D$2:$D$13,"conciliado",'Conciliacion de compuestos'!$E$2:$E$13,"OK",'Conciliacion de compuestos'!$O$2:$O$13,A50))>0,IFERROR(TEXTJOIN(CHAR(10),TRUE,FILTER('Conciliacion de compuestos'!$A$2:$A$13,('Conciliacion de compuestos'!$D$2:$D$13="conciliado")*('Conciliacion de compuestos'!$E$2:$E$13="OK")*((('Conciliacion de compuestos'!$M$2:$M$13=A50)+('Conciliacion de compuestos'!$N$2:$N$13=A50)+('Conciliacion de compuestos'!$O$2:$O$13=A50))>0))),""),"") | G50: =IF(I50="conciliado","conciliado","por revisar") | I50: =IF(SUM(COUNTIFS('Conciliacion de compuestos'!$D$2:$D$13,"conciliado",'Conciliacion de compuestos'!$E$2:$E$13,"OK",'Conciliacion de compuestos'!$M$2:$M$13,A50),COUNTIFS('Conciliacion de compuestos'!$D$2:$D$13,"conciliado",'Conciliacion de compuestos'!$E$2:$E$13,"OK",'Conciliacion de compuestos'!$N$2:$N$13,A50),COUNTIFS('Conciliacion de compuestos'!$D$2:$D$13,"conciliado",'Conciliacion de compuestos'!$E$2:$E$13,"OK",'Conciliacion de compuestos'!$O$2:$O$13,A50))>0,"conciliado","por revisar")
A51: 59 | B51: 46029 | C51: marquez nanc narvaez | D51: 28000 | E51: =IF(G51="conciliado","conciliado",I51) | F51: =IF(SUM(COUNTIFS('Conciliacion de compuestos'!$D$2:$D$13,"conciliado",'Conciliacion de compuestos'!$E$2:$E$13,"OK",'Conciliacion de compuestos'!$M$2:$M$13,A51),COUNTIFS('Conciliacion de compuestos'!$D$2:$D$13,"conciliado",'Conciliacion de compuestos'!$E$2:$E$13,"OK",'Conciliacion de compuestos'!$N$2:$N$13,A51),COUNTIFS('Conciliacion de compuestos'!$D$2:$D$13,"conciliado",'Conciliacion de compuestos'!$E$2:$E$13,"OK",'Conciliacion de compuestos'!$O$2:$O$13,A51))>0,IFERROR(TEXTJOIN(CHAR(10),TRUE,FILTER('Conciliacion de compuestos'!$A$2:$A$13,('Conciliacion de compuestos'!$D$2:$D$13="conciliado")*('Conciliacion de compuestos'!$E$2:$E$13="OK")*((('Conciliacion de compuestos'!$M$2:$M$13=A51)+('Conciliacion de compuestos'!$N$2:$N$13=A51)+('Conciliacion de compuestos'!$O$2:$O$13=A51))>0))),""),"") | G51: =IF(I51="conciliado","conciliado","por revisar") | I51: =IF(SUM(COUNTIFS('Conciliacion de compuestos'!$D$2:$D$13,"conciliado",'Conciliacion de compuestos'!$E$2:$E$13,"OK",'Conciliacion de compuestos'!$M$2:$M$13,A51),COUNTIFS('Conciliacion de compuestos'!$D$2:$D$13,"conciliado",'Conciliacion de compuestos'!$E$2:$E$13,"OK",'Conciliacion de compuestos'!$N$2:$N$13,A51),COUNTIFS('Conciliacion de compuestos'!$D$2:$D$13,"conciliado",'Conciliacion de compuestos'!$E$2:$E$13,"OK",'Conciliacion de compuestos'!$O$2:$O$13,A51))>0,"conciliado","por revisar")
A52: 60 | B52: 46029 | C52: lemus martinez pasto | D52: 52600 | E52: =IF(G52="conciliado","conciliado",I52) | F52: =IF(SUM(COUNTIFS('Conciliacion de compuestos'!$D$2:$D$13,"conciliado",'Conciliacion de compuestos'!$E$2:$E$13,"OK",'Conciliacion de compuestos'!$M$2:$M$13,A52),COUNTIFS('Conciliacion de compuestos'!$D$2:$D$13,"conciliado",'Conciliacion de compuestos'!$E$2:$E$13,"OK",'Conciliacion de compuestos'!$N$2:$N$13,A52),COUNTIFS('Conciliacion de compuestos'!$D$2:$D$13,"conciliado",'Conciliacion de compuestos'!$E$2:$E$13,"OK",'Conciliacion de compuestos'!$O$2:$O$13,A52))>0,IFERROR(TEXTJOIN(CHAR(10),TRUE,FILTER('Conciliacion de compuestos'!$A$2:$A$13,('Conciliacion de compuestos'!$D$2:$D$13="conciliado")*('Conciliacion de compuestos'!$E$2:$E$13="OK")*((('Conciliacion de compuestos'!$M$2:$M$13=A52)+('Conciliacion de compuestos'!$N$2:$N$13=A52)+('Conciliacion de compuestos'!$O$2:$O$13=A52))>0))),""),"") | G52: =IF(I52="conciliado","conciliado","por revisar") | I52: =IF(SUM(COUNTIFS('Conciliacion de compuestos'!$D$2:$D$13,"conciliado",'Conciliacion de compuestos'!$E$2:$E$13,"OK",'Conciliacion de compuestos'!$M$2:$M$13,A52),COUNTIFS('Conciliacion de compuestos'!$D$2:$D$13,"conciliado",'Conciliacion de compuestos'!$E$2:$E$13,"OK",'Conciliacion de compuestos'!$N$2:$N$13,A52),COUNTIFS('Conciliacion de compuestos'!$D$2:$D$13,"conciliado",'Conciliacion de compuestos'!$E$2:$E$13,"OK",'Conciliacion de compuestos'!$O$2:$O$13,A52))>0,"conciliado","por revisar")
A53: 63 | B53: 46029 | C53: buelvas diaz jose mi | D53: 55800 | E53: =IF(G53="conciliado","conciliado",I53) | F53: =IF(SUM(COUNTIFS('Conciliacion de compuestos'!$D$2:$D$13,"conciliado",'Conciliacion de compuestos'!$E$2:$E$13,"OK",'Conciliacion de compuestos'!$M$2:$M$13,A53),COUNTIFS('Conciliacion de compuestos'!$D$2:$D$13,"conciliado",'Conciliacion de compuestos'!$E$2:$E$13,"OK",'Conciliacion de compuestos'!$N$2:$N$13,A53),COUNTIFS('Conciliacion de compuestos'!$D$2:$D$13,"conciliado",'Conciliacion de compuestos'!$E$2:$E$13,"OK",'Conciliacion de compuestos'!$O$2:$O$13,A53))>0,IFERROR(TEXTJOIN(CHAR(10),TRUE,FILTER('Conciliacion de compuestos'!$A$2:$A$13,('Conciliacion de compuestos'!$D$2:$D$13="conciliado")*('Conciliacion de compuestos'!$E$2:$E$13="OK")*((('Conciliacion de compuestos'!$M$2:$M$13=A53)+('Conciliacion de compuestos'!$N$2:$N$13=A53)+('Conciliacion de compuestos'!$O$2:$O$13=A53))>0))),""),"") | G53: =IF(I53="conciliado","conciliado","por revisar") | I53: =IF(SUM(COUNTIFS('Conciliacion de compuestos'!$D$2:$D$13,"conciliado",'Conciliacion de compuestos'!$E$2:$E$13,"OK",'Conciliacion de compuestos'!$M$2:$M$13,A53),COUNTIFS('Conciliacion de compuestos'!$D$2:$D$13,"conciliado",'Conciliacion de compuestos'!$E$2:$E$13,"OK",'Conciliacion de compuestos'!$N$2:$N$13,A53),COUNTIFS('Conciliacion de compuestos'!$D$2:$D$13,"conciliado",'Conciliacion de compuestos'!$E$2:$E$13,"OK",'Conciliacion de compuestos'!$O$2:$O$13,A53))>0,"conciliado","por revisar")
A54: 58 | B54: 46029 | C54: jorge mosquera ramos | D54: 429310 | E54: =IF(G54="conciliado","conciliado",I54) | F54: =IF(SUM(COUNTIFS('Conciliacion de compuestos'!$D$2:$D$13,"conciliado",'Conciliacion de compuestos'!$E$2:$E$13,"OK",'Conciliacion de compuestos'!$M$2:$M$13,A54),COUNTIFS('Conciliacion de compuestos'!$D$2:$D$13,"conciliado",'Conciliacion de compuestos'!$E$2:$E$13,"OK",'Conciliacion de compuestos'!$N$2:$N$13,A54),COUNTIFS('Conciliacion de compuestos'!$D$2:$D$13,"conciliado",'Conciliacion de compuestos'!$E$2:$E$13,"OK",'Conciliacion de compuestos'!$O$2:$O$13,A54))>0,IFERROR(TEXTJOIN(CHAR(10),TRUE,FILTER('Conciliacion de compuestos'!$A$2:$A$13,('Conciliacion de compuestos'!$D$2:$D$13="conciliado")*('Conciliacion de compuestos'!$E$2:$E$13="OK")*((('Conciliacion de compuestos'!$M$2:$M$13=A54)+('Conciliacion de compuestos'!$N$2:$N$13=A54)+('Conciliacion de compuestos'!$O$2:$O$13=A54))>0))),""),"") | G54: =IF(I54="conciliado","conciliado","por revisar") | I54: =IF(SUM(COUNTIFS('Conciliacion de compuestos'!$D$2:$D$13,"conciliado",'Conciliacion de compuestos'!$E$2:$E$13,"OK",'Conciliacion de compuestos'!$M$2:$M$13,A54),COUNTIFS('Conciliacion de compuestos'!$D$2:$D$13,"conciliado",'Conciliacion de compuestos'!$E$2:$E$13,"OK",'Conciliacion de compuestos'!$N$2:$N$13,A54),COUNTIFS('Conciliacion de compuestos'!$D$2:$D$13,"conciliado",'Conciliacion de compuestos'!$E$2:$E$13,"OK",'Conciliacion de compuestos'!$O$2:$O$13,A54))>0,"conciliado","por revisar")
A55: 67 | B55: 46029 | C55: aragon diego salazar | D55: 80500 | E55: =IF(G55="conciliado","conciliado",I55) | F55: =IF(SUM(COUNTIFS('Conciliacion de compuestos'!$D$2:$D$13,"conciliado",'Conciliacion de compuestos'!$E$2:$E$13,"OK",'Conciliacion de compuestos'!$M$2:$M$13,A55),COUNTIFS('Conciliacion de compuestos'!$D$2:$D$13,"conciliado",'Conciliacion de compuestos'!$E$2:$E$13,"OK",'Conciliacion de compuestos'!$N$2:$N$13,A55),COUNTIFS('Conciliacion de compuestos'!$D$2:$D$13,"conciliado",'Conciliacion de compuestos'!$E$2:$E$13,"OK",'Conciliacion de compuestos'!$O$2:$O$13,A55))>0,IFERROR(TEXTJOIN(CHAR(10),TRUE,FILTER('Conciliacion de compuestos'!$A$2:$A$13,('Conciliacion de compuestos'!$D$2:$D$13="conciliado")*('Conciliacion de compuestos'!$E$2:$E$13="OK")*((('Conciliacion de compuestos'!$M$2:$M$13=A55)+('Conciliacion de compuestos'!$N$2:$N$13=A55)+('Conciliacion de compuestos'!$O$2:$O$13=A55))>0))),""),"") | G55: =IF(I55="conciliado","conciliado","por revisar") | I55: =IF(SUM(COUNTIFS('Conciliacion de compuestos'!$D$2:$D$13,"conciliado",'Conciliacion de compuestos'!$E$2:$E$13,"OK",'Conciliacion de compuestos'!$M$2:$M$13,A55),COUNTIFS('Conciliacion de compuestos'!$D$2:$D$13,"conciliado",'Conciliacion de compuestos'!$E$2:$E$13,"OK",'Conciliacion de compuestos'!$N$2:$N$13,A55),COUNTIFS('Conciliacion de compuestos'!$D$2:$D$13,"conciliado",'Conciliacion de compuestos'!$E$2:$E$13,"OK",'Conciliacion de compuestos'!$O$2:$O$13,A55))>0,"conciliado","por revisar")
A56: 65 | B56: 46029 | C56: bastidas edi jurado | D56: 52800 | E56: =IF(G56="conciliado","conciliado",I56) | F56: =IF(SUM(COUNTIFS('Conciliacion de compuestos'!$D$2:$D$13,"conciliado",'Conciliacion de compuestos'!$E$2:$E$13,"OK",'Conciliacion de compuestos'!$M$2:$M$13,A56),COUNTIFS('Conciliacion de compuestos'!$D$2:$D$13,"conciliado",'Conciliacion de compuestos'!$E$2:$E$13,"OK",'Conciliacion de compuestos'!$N$2:$N$13,A56),COUNTIFS('Conciliacion de compuestos'!$D$2:$D$13,"conciliado",'Conciliacion de compuestos'!$E$2:$E$13,"OK",'Conciliacion de compuestos'!$O$2:$O$13,A56))>0,IFERROR(TEXTJOIN(CHAR(10),TRUE,FILTER('Conciliacion de compuestos'!$A$2:$A$13,('Conciliacion de compuestos'!$D$2:$D$13="conciliado")*('Conciliacion de compuestos'!$E$2:$E$13="OK")*((('Conciliacion de compuestos'!$M$2:$M$13=A56)+('Conciliacion de compuestos'!$N$2:$N$13=A56)+('Conciliacion de compuestos'!$O$2:$O$13=A56))>0))),""),"") | G56: =IF(I56="conciliado","conciliado","por revisar") | I56: =IF(SUM(COUNTIFS('Conciliacion de compuestos'!$D$2:$D$13,"conciliado",'Conciliacion de compuestos'!$E$2:$E$13,"OK",'Conciliacion de compuestos'!$M$2:$M$13,A56),COUNTIFS('Conciliacion de compuestos'!$D$2:$D$13,"conciliado",'Conciliacion de compuestos'!$E$2:$E$13,"OK",'Conciliacion de compuestos'!$N$2:$N$13,A56),COUNTIFS('Conciliacion de compuestos'!$D$2:$D$13,"conciliado",'Conciliacion de compuestos'!$E$2:$E$13,"OK",'Conciliacion de compuestos'!$O$2:$O$13,A56))>0,"conciliado","por revisar")
A57: 61 | B57: 46029 | C57: acosta jaiber rosero | D57: 120400 | E57: =IF(G57="conciliado","conciliado",I57) | F57: =IF(SUM(COUNTIFS('Conciliacion de compuestos'!$D$2:$D$13,"conciliado",'Conciliacion de compuestos'!$E$2:$E$13,"OK",'Conciliacion de compuestos'!$M$2:$M$13,A57),COUNTIFS('Conciliacion de compuestos'!$D$2:$D$13,"conciliado",'Conciliacion de compuestos'!$E$2:$E$13,"OK",'Conciliacion de compuestos'!$N$2:$N$13,A57),COUNTIFS('Conciliacion de compuestos'!$D$2:$D$13,"conciliado",'Conciliacion de compuestos'!$E$2:$E$13,"OK",'Conciliacion de compuestos'!$O$2:$O$13,A57))>0,IFERROR(TEXTJOIN(CHAR(10),TRUE,FILTER('Conciliacion de compuestos'!$A$2:$A$13,('Conciliacion de compuestos'!$D$2:$D$13="conciliado")*('Conciliacion de compuestos'!$E$2:$E$13="OK")*((('Conciliacion de compuestos'!$M$2:$M$13=A57)+('Conciliacion de compuestos'!$N$2:$N$13=A57)+('Conciliacion de compuestos'!$O$2:$O$13=A57))>0))),""),"") | G57: =IF(I57="conciliado","conciliado","por revisar") | I57: =IF(SUM(COUNTIFS('Conciliacion de compuestos'!$D$2:$D$13,"conciliado",'Conciliacion de compuestos'!$E$2:$E$13,"OK",'Conciliacion de compuestos'!$M$2:$M$13,A57),COUNTIFS('Conciliacion de compuestos'!$D$2:$D$13,"conciliado",'Conciliacion de compuestos'!$E$2:$E$13,"OK",'Conciliacion de compuestos'!$N$2:$N$13,A57),COUNTIFS('Conciliacion de compuestos'!$D$2:$D$13,"conciliado",'Conciliacion de compuestos'!$E$2:$E$13,"OK",'Conciliacion de compuestos'!$O$2:$O$13,A57))>0,"conciliado","por revisar")
A58: 78 | B58: 46030 | C58: arenas bray melendez | D58: 38900 | E58: =IF(G58="conciliado","conciliado",I58) | F58: =IF(SUM(COUNTIFS('Conciliacion de compuestos'!$D$2:$D$13,"conciliado",'Conciliacion de compuestos'!$E$2:$E$13,"OK",'Conciliacion de compuestos'!$M$2:$M$13,A58),COUNTIFS('Conciliacion de compuestos'!$D$2:$D$13,"conciliado",'Conciliacion de compuestos'!$E$2:$E$13,"OK",'Conciliacion de compuestos'!$N$2:$N$13,A58),COUNTIFS('Conciliacion de compuestos'!$D$2:$D$13,"conciliado",'Conciliacion de compuestos'!$E$2:$E$13,"OK",'Conciliacion de compuestos'!$O$2:$O$13,A58))>0,IFERROR(TEXTJOIN(CHAR(10),TRUE,FILTER('Conciliacion de compuestos'!$A$2:$A$13,('Conciliacion de compuestos'!$D$2:$D$13="conciliado")*('Conciliacion de compuestos'!$E$2:$E$13="OK")*((('Conciliacion de compuestos'!$M$2:$M$13=A58)+('Conciliacion de compuestos'!$N$2:$N$13=A58)+('Conciliacion de compuestos'!$O$2:$O$13=A58))>0))),""),"") | G58: =IF(I58="conciliado","conciliado","por revisar") | I58: =IF(SUM(COUNTIFS('Conciliacion de compuestos'!$D$2:$D$13,"conciliado",'Conciliacion de compuestos'!$E$2:$E$13,"OK",'Conciliacion de compuestos'!$M$2:$M$13,A58),COUNTIFS('Conciliacion de compuestos'!$D$2:$D$13,"conciliado",'Conciliacion de compuestos'!$E$2:$E$13,"OK",'Conciliacion de compuestos'!$N$2:$N$13,A58),COUNTIFS('Conciliacion de compuestos'!$D$2:$D$13,"conciliado",'Conciliacion de compuestos'!$E$2:$E$13,"OK",'Conciliacion de compuestos'!$O$2:$O$13,A58))>0,"conciliado","por revisar")
A59: 69 | B59: 46030 | C59: angulo benavides yad | D59: 46400 | E59: =IF(G59="conciliado","conciliado",I59) | F59: =IF(SUM(COUNTIFS('Conciliacion de compuestos'!$D$2:$D$13,"conciliado",'Conciliacion de compuestos'!$E$2:$E$13,"OK",'Conciliacion de compuestos'!$M$2:$M$13,A59),COUNTIFS('Conciliacion de compuestos'!$D$2:$D$13,"conciliado",'Conciliacion de compuestos'!$E$2:$E$13,"OK",'Conciliacion de compuestos'!$N$2:$N$13,A59),COUNTIFS('Conciliacion de compuestos'!$D$2:$D$13,"conciliado",'Conciliacion de compuestos'!$E$2:$E$13,"OK",'Conciliacion de compuestos'!$O$2:$O$13,A59))>0,IFERROR(TEXTJOIN(CHAR(10),TRUE,FILTER('Conciliacion de compuestos'!$A$2:$A$13,('Conciliacion de compuestos'!$D$2:$D$13="conciliado")*('Conciliacion de compuestos'!$E$2:$E$13="OK")*((('Conciliacion de compuestos'!$M$2:$M$13=A59)+('Conciliacion de compuestos'!$N$2:$N$13=A59)+('Conciliacion de compuestos'!$O$2:$O$13=A59))>0))),""),"") | G59: =IF(I59="conciliado","conciliado","por revisar") | I59: =IF(SUM(COUNTIFS('Conciliacion de compuestos'!$D$2:$D$13,"conciliado",'Conciliacion de compuestos'!$E$2:$E$13,"OK",'Conciliacion de compuestos'!$M$2:$M$13,A59),COUNTIFS('Conciliacion de compuestos'!$D$2:$D$13,"conciliado",'Conciliacion de compuestos'!$E$2:$E$13,"OK",'Conciliacion de compuestos'!$N$2:$N$13,A59),COUNTIFS('Conciliacion de compuestos'!$D$2:$D$13,"conciliado",'Conciliacion de compuestos'!$E$2:$E$13,"OK",'Conciliacion de compuestos'!$O$2:$O$13,A59))>0,"conciliado","por revisar")
A60: 73 | B60: 46030 | C60: hurtado jhon noguera | D60: 63200 | E60: =IF(G60="conciliado","conciliado",I60) | F60: =IF(SUM(COUNTIFS('Conciliacion de compuestos'!$D$2:$D$13,"conciliado",'Conciliacion de compuestos'!$E$2:$E$13,"OK",'Conciliacion de compuestos'!$M$2:$M$13,A60),COUNTIFS('Conciliacion de compuestos'!$D$2:$D$13,"conciliado",'Conciliacion de compuestos'!$E$2:$E$13,"OK",'Conciliacion de compuestos'!$N$2:$N$13,A60),COUNTIFS('Conciliacion de compuestos'!$D$2:$D$13,"conciliado",'Conciliacion de compuestos'!$E$2:$E$13,"OK",'Conciliacion de compuestos'!$O$2:$O$13,A60))>0,IFERROR(TEXTJOIN(CHAR(10),TRUE,FILTER('Conciliacion de compuestos'!$A$2:$A$13,('Conciliacion de compuestos'!$D$2:$D$13="conciliado")*('Conciliacion de compuestos'!$E$2:$E$13="OK")*((('Conciliacion de compuestos'!$M$2:$M$13=A60)+('Conciliacion de compuestos'!$N$2:$N$13=A60)+('Conciliacion de compuestos'!$O$2:$O$13=A60))>0))),""),"") | G60: =IF(I60="conciliado","conciliado","por revisar") | I60: =IF(SUM(COUNTIFS('Conciliacion de compuestos'!$D$2:$D$13,"conciliado",'Conciliacion de compuestos'!$E$2:$E$13,"OK",'Conciliacion de compuestos'!$M$2:$M$13,A60),COUNTIFS('Conciliacion de compuestos'!$D$2:$D$13,"conciliado",'Conciliacion de compuestos'!$E$2:$E$13,"OK",'Conciliacion de compuestos'!$N$2:$N$13,A60),COUNTIFS('Conciliacion de compuestos'!$D$2:$D$13,"conciliado",'Conciliacion de compuestos'!$E$2:$E$13,"OK",'Conciliacion de compuestos'!$O$2:$O$13,A60))>0,"conciliado","por revisar")
A61: 68 | B61: 46030 | C61: lemus martinez pasto | D61: 31070 | E61: =IF(G61="conciliado","conciliado",I61) | F61: =IF(SUM(COUNTIFS('Conciliacion de compuestos'!$D$2:$D$13,"conciliado",'Conciliacion de compuestos'!$E$2:$E$13,"OK",'Conciliacion de compuestos'!$M$2:$M$13,A61),COUNTIFS('Conciliacion de compuestos'!$D$2:$D$13,"conciliado",'Conciliacion de compuestos'!$E$2:$E$13,"OK",'Conciliacion de compuestos'!$N$2:$N$13,A61),COUNTIFS('Conciliacion de compuestos'!$D$2:$D$13,"conciliado",'Conciliacion de compuestos'!$E$2:$E$13,"OK",'Conciliacion de compuestos'!$O$2:$O$13,A61))>0,IFERROR(TEXTJOIN(CHAR(10),TRUE,FILTER('Conciliacion de compuestos'!$A$2:$A$13,('Conciliacion de compuestos'!$D$2:$D$13="conciliado")*('Conciliacion de compuestos'!$E$2:$E$13="OK")*((('Conciliacion de compuestos'!$M$2:$M$13=A61)+('Conciliacion de compuestos'!$N$2:$N$13=A61)+('Conciliacion de compuestos'!$O$2:$O$13=A61))>0))),""),"") | G61: =IF(I61="conciliado","conciliado","por revisar") | I61: =IF(SUM(COUNTIFS('Conciliacion de compuestos'!$D$2:$D$13,"conciliado",'Conciliacion de compuestos'!$E$2:$E$13,"OK",'Conciliacion de compuestos'!$M$2:$M$13,A61),COUNTIFS('Conciliacion de compuestos'!$D$2:$D$13,"conciliado",'Conciliacion de compuestos'!$E$2:$E$13,"OK",'Conciliacion de compuestos'!$N$2:$N$13,A61),COUNTIFS('Conciliacion de compuestos'!$D$2:$D$13,"conciliado",'Conciliacion de compuestos'!$E$2:$E$13,"OK",'Conciliacion de compuestos'!$O$2:$O$13,A61))>0,"conciliado","por revisar")
... A67: 105 | B67: 46034 | C67: claudio eraso munoz | D67: 40700 | E67: =IF(G67="conciliado","conciliado",I67) | F67: =IF(SUM(COUNTIFS('Conciliacion de compuestos'!$D$2:$D$13,"conciliado",'Conciliacion de compuestos'!$E$2:$E$13,"OK",'Conciliacion de compuestos'!$M$2:$M$13,A67),COUNTIFS('Conciliacion de compuestos'!$D$2:$D$13,"conciliado",'Conciliacion de compuestos'!$E$2:$E$13,"OK",'Conciliacion de compuestos'!$N$2:$N$13,A67),COUNTIFS('Conciliacion de compuestos'!$D$2:$D$13,"conciliado",'Conciliacion de compuestos'!$E$2:$E$13,"OK",'Conciliacion de compuestos'!$O$2:$O$13,A67))>0,IFERROR(TEXTJOIN(CHAR(10),TRUE,FILTER('Conciliacion de compuestos'!$A$2:$A$13,('Conciliacion de compuestos'!$D$2:$D$13="conciliado")*('Conciliacion de compuestos'!$E$2:$E$13="OK")*((('Conciliacion de compuestos'!$M$2:$M$13=A67)+('Conciliacion de compuestos'!$N$2:$N$13=A67)+('Conciliacion de compuestos'!$O$2:$O$13=A67))>0))),""),"") | G67: =IF(I67="conciliado","conciliado","por revisar") | I67: =IF(SUM(COUNTIFS('Conciliacion de compuestos'!$D$2:$D$13,"conciliado",'Conciliacion de compuestos'!$E$2:$E$13,"OK",'Conciliacion de compuestos'!$M$2:$M$13,A67),COUNTIFS('Conciliacion de compuestos'!$D$2:$D$13,"conciliado",'Conciliacion de compuestos'!$E$2:$E$13,"OK",'Conciliacion de compuestos'!$N$2:$N$13,A67),COUNTIFS('Conciliacion de compuestos'!$D$2:$D$13,"conciliado",'Conciliacion de compuestos'!$E$2:$E$13,"OK",'Conciliacion de compuestos'!$O$2:$O$13,A67))>0,"conciliado","por revisar")
A68: 122 | B68: 46035 | C68: ciro gonzalez santos | D68: 20000 | E68: =IF(G68="conciliado","conciliado",I68) | F68: 670 | 2026-01-13 | 20,000 | consignacion credibanco d e | G68: =IF(I68="conciliado","conciliado","por revisar") | I68: conciliado
A69: 112 | B69: 46034 | C69: castaneda rodriguez | D69: 16800 | E69: =IF(G69="conciliado","conciliado",I69) | F69: =IF(SUM(COUNTIFS('Conciliacion de compuestos'!$D$2:$D$13,"conciliado",'Conciliacion de compuestos'!$E$2:$E$13,"OK",'Conciliacion de compuestos'!$M$2:$M$13,A69),COUNTIFS('Conciliacion de compuestos'!$D$2:$D$13,"conciliado",'Conciliacion de compuestos'!$E$2:$E$13,"OK",'Conciliacion de compuestos'!$N$2:$N$13,A69),COUNTIFS('Conciliacion de compuestos'!$D$2:$D$13,"conciliado",'Conciliacion de compuestos'!$E$2:$E$13,"OK",'Conciliacion de compuestos'!$O$2:$O$13,A69))>0,IFERROR(TEXTJOIN(CHAR(10),TRUE,FILTER('Conciliacion de compuestos'!$A$2:$A$13,('Conciliacion de compuestos'!$D$2:$D$13="conciliado")*('Conciliacion de compuestos'!$E$2:$E$13="OK")*((('Conciliacion de compuestos'!$M$2:$M$13=A69)+('Conciliacion de compuestos'!$N$2:$N$13=A69)+('Conciliacion de compuestos'!$O$2:$O$13=A69))>0))),""),"") | G69: =IF(I69="conciliado","conciliado","por revisar") | I69: =IF(SUM(COUNTIFS('Conciliacion de compuestos'!$D$2:$D$13,"conciliado",'Conciliacion de compuestos'!$E$2:$E$13,"OK",'Conciliacion de compuestos'!$M$2:$M$13,A69),COUNTIFS('Conciliacion de compuestos'!$D$2:$D$13,"conciliado",'Conciliacion de compuestos'!$E$2:$E$13,"OK",'Conciliacion de compuestos'!$N$2:$N$13,A69),COUNTIFS('Conciliacion de compuestos'!$D$2:$D$13,"conciliado",'Conciliacion de compuestos'!$E$2:$E$13,"OK",'Conciliacion de compuestos'!$O$2:$O$13,A69))>0,"conciliado","por revisar")
A70: 104 | B70: 46034 | C70: anyela diaz meneses | D70: 23100 | E70: =IF(G70="conciliado","conciliado",I70) | F70: =IF(SUM(COUNTIFS('Conciliacion de compuestos'!$D$2:$D$13,"conciliado",'Conciliacion de compuestos'!$E$2:$E$13,"OK",'Conciliacion de compuestos'!$M$2:$M$13,A70),COUNTIFS('Conciliacion de compuestos'!$D$2:$D$13,"conciliado",'Conciliacion de compuestos'!$E$2:$E$13,"OK",'Conciliacion de compuestos'!$N$2:$N$13,A70),COUNTIFS('Conciliacion de compuestos'!$D$2:$D$13,"conciliado",'Conciliacion de compuestos'!$E$2:$E$13,"OK",'Conciliacion de compuestos'!$O$2:$O$13,A70))>0,IFERROR(TEXTJOIN(CHAR(10),TRUE,FILTER('Conciliacion de compuestos'!$A$2:$A$13,('Conciliacion de compuestos'!$D$2:$D$13="conciliado")*('Conciliacion de compuestos'!$E$2:$E$13="OK")*((('Conciliacion de compuestos'!$M$2:$M$13=A70)+('Conciliacion de compuestos'!$N$2:$N$13=A70)+('Conciliacion de compuestos'!$O$2:$O$13=A70))>0))),""),"") | G70: =IF(I70="conciliado","conciliado","por revisar") | I70: =IF(SUM(COUNTIFS('Conciliacion de compuestos'!$D$2:$D$13,"conciliado",'Conciliacion de compuestos'!$E$2:$E$13,"OK",'Conciliacion de compuestos'!$M$2:$M$13,A70),COUNTIFS('Conciliacion de compuestos'!$D$2:$D$13,"conciliado",'Conciliacion de compuestos'!$E$2:$E$13,"OK",'Conciliacion de compuestos'!$N$2:$N$13,A70),COUNTIFS('Conciliacion de compuestos'!$D$2:$D$13,"conciliado",'Conciliacion de compuestos'!$E$2:$E$13,"OK",'Conciliacion de compuestos'!$O$2:$O$13,A70))>0,"conciliado","por revisar")
A71: 106 | B71: 46034 | C71: bastidas bolanos pao | D71: 24245 | E71: =IF(G71="conciliado","conciliado",I71) | F71: =IF(SUM(COUNTIFS('Conciliacion de compuestos'!$D$2:$D$13,"conciliado",'Conciliacion de compuestos'!$E$2:$E$13,"OK",'Conciliacion de compuestos'!$M$2:$M$13,A71),COUNTIFS('Conciliacion de compuestos'!$D$2:$D$13,"conciliado",'Conciliacion de compuestos'!$E$2:$E$13,"OK",'Conciliacion de compuestos'!$N$2:$N$13,A71),COUNTIFS('Conciliacion de compuestos'!$D$2:$D$13,"conciliado",'Conciliacion de compuestos'!$E$2:$E$13,"OK",'Conciliacion de compuestos'!$O$2:$O$13,A71))>0,IFERROR(TEXTJOIN(CHAR(10),TRUE,FILTER('Conciliacion de compuestos'!$A$2:$A$13,('Conciliacion de compuestos'!$D$2:$D$13="conciliado")*('Conciliacion de compuestos'!$E$2:$E$13="OK")*((('Conciliacion de compuestos'!$M$2:$M$13=A71)+('Conciliacion de compuestos'!$N$2:$N$13=A71)+('Conciliacion de compuestos'!$O$2:$O$13=A71))>0))),""),"") | G71: =IF(I71="conciliado","conciliado","por revisar") | I71: =IF(SUM(COUNTIFS('Conciliacion de compuestos'!$D$2:$D$13,"conciliado",'Conciliacion de compuestos'!$E$2:$E$13,"OK",'Conciliacion de compuestos'!$M$2:$M$13,A71),COUNTIFS('Conciliacion de compuestos'!$D$2:$D$13,"conciliado",'Conciliacion de compuestos'!$E$2:$E$13,"OK",'Conciliacion de compuestos'!$N$2:$N$13,A71),COUNTIFS('Conciliacion de compuestos'!$D$2:$D$13,"conciliado",'Conciliacion de compuestos'!$E$2:$E$13,"OK",'Conciliacion de compuestos'!$O$2:$O$13,A71))>0,"conciliado","por revisar")
A72: 108 | B72: 46034 | C72: dayan florez l reyes | D72: 81400 | E72: =IF(G72="conciliado","conciliado",I72) | F72: =IF(SUM(COUNTIFS('Conciliacion de compuestos'!$D$2:$D$13,"conciliado",'Conciliacion de compuestos'!$E$2:$E$13,"OK",'Conciliacion de compuestos'!$M$2:$M$13,A72),COUNTIFS('Conciliacion de compuestos'!$D$2:$D$13,"conciliado",'Conciliacion de compuestos'!$E$2:$E$13,"OK",'Conciliacion de compuestos'!$N$2:$N$13,A72),COUNTIFS('Conciliacion de compuestos'!$D$2:$D$13,"conciliado",'Conciliacion de compuestos'!$E$2:$E$13,"OK",'Conciliacion de compuestos'!$O$2:$O$13,A72))>0,IFERROR(TEXTJOIN(CHAR(10),TRUE,FILTER('Conciliacion de compuestos'!$A$2:$A$13,('Conciliacion de compuestos'!$D$2:$D$13="conciliado")*('Conciliacion de compuestos'!$E$2:$E$13="OK")*((('Conciliacion de compuestos'!$M$2:$M$13=A72)+('Conciliacion de compuestos'!$N$2:$N$13=A72)+('Conciliacion de compuestos'!$O$2:$O$13=A72))>0))),""),"") | G72: =IF(I72="conciliado","conciliado","por revisar") | I72: =IF(SUM(COUNTIFS('Conciliacion de compuestos'!$D$2:$D$13,"conciliado",'Conciliacion de compuestos'!$E$2:$E$13,"OK",'Conciliacion de compuestos'!$M$2:$M$13,A72),COUNTIFS('Conciliacion de compuestos'!$D$2:$D$13,"conciliado",'Conciliacion de compuestos'!$E$2:$E$13,"OK",'Conciliacion de compuestos'!$N$2:$N$13,A72),COUNTIFS('Conciliacion de compuestos'!$D$2:$D$13,"conciliado",'Conciliacion de compuestos'!$E$2:$E$13,"OK",'Conciliacion de compuestos'!$O$2:$O$13,A72))>0,"conciliado","por revisar")
A73: 110 | B73: 46034 | C73: al enriquez yaguapaz | D73: 35656 | E73: =IF(G73="conciliado","conciliado",I73) | F73: =IF(SUM(COUNTIFS('Conciliacion de compuestos'!$D$2:$D$13,"conciliado",'Conciliacion de compuestos'!$E$2:$E$13,"OK",'Conciliacion de compuestos'!$M$2:$M$13,A73),COUNTIFS('Conciliacion de compuestos'!$D$2:$D$13,"conciliado",'Conciliacion de compuestos'!$E$2:$E$13,"OK",'Conciliacion de compuestos'!$N$2:$N$13,A73),COUNTIFS('Conciliacion de compuestos'!$D$2:$D$13,"conciliado",'Conciliacion de compuestos'!$E$2:$E$13,"OK",'Conciliacion de compuestos'!$O$2:$O$13,A73))>0,IFERROR(TEXTJOIN(CHAR(10),TRUE,FILTER('Conciliacion de compuestos'!$A$2:$A$13,('Conciliacion de compuestos'!$D$2:$D$13="conciliado")*('Conciliacion de compuestos'!$E$2:$E$13="OK")*((('Conciliacion de compuestos'!$M$2:$M$13=A73)+('Conciliacion de compuestos'!$N$2:$N$13=A73)+('Conciliacion de compuestos'!$O$2:$O$13=A73))>0))),""),"") | G73: =IF(I73="conciliado","conciliado","por revisar") | I73: =IF(SUM(COUNTIFS('Conciliacion de compuestos'!$D$2:$D$13,"conciliado",'Conciliacion de compuestos'!$E$2:$E$13,"OK",'Conciliacion de compuestos'!$M$2:$M$13,A73),COUNTIFS('Conciliacion de compuestos'!$D$2:$D$13,"conciliado",'Conciliacion de compuestos'!$E$2:$E$13,"OK",'Conciliacion de compuestos'!$N$2:$N$13,A73),COUNTIFS('Conciliacion de compuestos'!$D$2:$D$13,"conciliado",'Conciliacion de compuestos'!$E$2:$E$13,"OK",'Conciliacion de compuestos'!$O$2:$O$13,A73))>0,"conciliado","por revisar")
A74: 82 | B74: 46031 | C74: alba arango meza pat | D74: 124100 | E74: =IF(G74="conciliado","conciliado",I74) | F74: =IF(SUM(COUNTIFS('Conciliacion de compuestos'!$D$2:$D$13,"conciliado",'Conciliacion de compuestos'!$E$2:$E$13,"OK",'Conciliacion de compuestos'!$M$2:$M$13,A74),COUNTIFS('Conciliacion de compuestos'!$D$2:$D$13,"conciliado",'Conciliacion de compuestos'!$E$2:$E$13,"OK",'Conciliacion de compuestos'!$N$2:$N$13,A74),COUNTIFS('Conciliacion de compuestos'!$D$2:$D$13,"conciliado",'Conciliacion de compuestos'!$E$2:$E$13,"OK",'Conciliacion de compuestos'!$O$2:$O$13,A74))>0,IFERROR(TEXTJOIN(CHAR(10),TRUE,FILTER('Conciliacion de compuestos'!$A$2:$A$13,('Conciliacion de compuestos'!$D$2:$D$13="conciliado")*('Conciliacion de compuestos'!$E$2:$E$13="OK")*((('Conciliacion de compuestos'!$M$2:$M$13=A74)+('Conciliacion de compuestos'!$N$2:$N$13=A74)+('Conciliacion de compuestos'!$O$2:$O$13=A74))>0))),""),"") | G74: =IF(I74="conciliado","conciliado","por revisar") | I74: =IF(SUM(COUNTIFS('Conciliacion de compuestos'!$D$2:$D$13,"conciliado",'Conciliacion de compuestos'!$E$2:$E$13,"OK",'Conciliacion de compuestos'!$M$2:$M$13,A74),COUNTIFS('Conciliacion de compuestos'!$D$2:$D$13,"conciliado",'Conciliacion de compuestos'!$E$2:$E$13,"OK",'Conciliacion de compuestos'!$N$2:$N$13,A74),COUNTIFS('Conciliacion de compuestos'!$D$2:$D$13,"conciliado",'Conciliacion de compuestos'!$E$2:$E$13,"OK",'Conciliacion de compuestos'!$O$2:$O$13,A74))>0,"conciliado","por revisar")
A75: 83 | B75: 46031 | C75: hoz la sanmiguel | D75: 44400 | E75: =IF(G75="conciliado","conciliado",I75) | F75: =IF(SUM(COUNTIFS('Conciliacion de compuestos'!$D$2:$D$13,"conciliado",'Conciliacion de compuestos'!$E$2:$E$13,"OK",'Conciliacion de compuestos'!$M$2:$M$13,A75),COUNTIFS('Conciliacion de compuestos'!$D$2:$D$13,"conciliado",'Conciliacion de compuestos'!$E$2:$E$13,"OK",'Conciliacion de compuestos'!$N$2:$N$13,A75),COUNTIFS('Conciliacion de compuestos'!$D$2:$D$13,"conciliado",'Conciliacion de compuestos'!$E$2:$E$13,"OK",'Conciliacion de compuestos'!$O$2:$O$13,A75))>0,IFERROR(TEXTJOIN(CHAR(10),TRUE,FILTER('Conciliacion de compuestos'!$A$2:$A$13,('Conciliacion de compuestos'!$D$2:$D$13="conciliado")*('Conciliacion de compuestos'!$E$2:$E$13="OK")*((('Conciliacion de compuestos'!$M$2:$M$13=A75)+('Conciliacion de compuestos'!$N$2:$N$13=A75)+('Conciliacion de compuestos'!$O$2:$O$13=A75))>0))),""),"") | G75: =IF(I75="conciliado","conciliado","por revisar") | I75: =IF(SUM(COUNTIFS('Conciliacion de compuestos'!$D$2:$D$13,"conciliado",'Conciliacion de compuestos'!$E$2:$E$13,"OK",'Conciliacion de compuestos'!$M$2:$M$13,A75),COUNTIFS('Conciliacion de compuestos'!$D$2:$D$13,"conciliado",'Conciliacion de compuestos'!$E$2:$E$13,"OK",'Conciliacion de compuestos'!$N$2:$N$13,A75),COUNTIFS('Conciliacion de compuestos'!$D$2:$D$13,"conciliado",'Conciliacion de compuestos'!$E$2:$E$13,"OK",'Conciliacion de compuestos'!$O$2:$O$13,A75))>0,"conciliado","por revisar")
A76: 85 | B76: 46031 | C76: bl castano tuberquia | D76: 100200 | E76: =IF(G76="conciliado","conciliado",I76) | F76: =IF(SUM(COUNTIFS('Conciliacion de compuestos'!$D$2:$D$13,"conciliado",'Conciliacion de compuestos'!$E$2:$E$13,"OK",'Conciliacion de compuestos'!$M$2:$M$13,A76),COUNTIFS('Conciliacion de compuestos'!$D$2:$D$13,"conciliado",'Conciliacion de compuestos'!$E$2:$E$13,"OK",'Conciliacion de compuestos'!$N$2:$N$13,A76),COUNTIFS('Conciliacion de compuestos'!$D$2:$D$13,"conciliado",'Conciliacion de compuestos'!$E$2:$E$13,"OK",'Conciliacion de compuestos'!$O$2:$O$13,A76))>0,IFERROR(TEXTJOIN(CHAR(10),TRUE,FILTER('Conciliacion de compuestos'!$A$2:$A$13,('Conciliacion de compuestos'!$D$2:$D$13="conciliado")*('Conciliacion de compuestos'!$E$2:$E$13="OK")*((('Conciliacion de compuestos'!$M$2:$M$13=A76)+('Conciliacion de compuestos'!$N$2:$N$13=A76)+('Conciliacion de compuestos'!$O$2:$O$13=A76))>0))),""),"") | G76: =IF(I76="conciliado","conciliado","por revisar") | I76: =IF(SUM(COUNTIFS('Conciliacion de compuestos'!$D$2:$D$13,"conciliado",'Conciliacion de compuestos'!$E$2:$E$13,"OK",'Conciliacion de compuestos'!$M$2:$M$13,A76),COUNTIFS('Conciliacion de compuestos'!$D$2:$D$13,"conciliado",'Conciliacion de compuestos'!$E$2:$E$13,"OK",'Conciliacion de compuestos'!$N$2:$N$13,A76),COUNTIFS('Conciliacion de compuestos'!$D$2:$D$13,"conciliado",'Conciliacion de compuestos'!$E$2:$E$13,"OK",'Conciliacion de compuestos'!$O$2:$O$13,A76))>0,"conciliado","por revisar")
A77: 90 | B77: 46032 | C77: arango mario meza | D77: 222700 | E77: =IF(G77="conciliado","conciliado",I77) | F77: =IF(SUM(COUNTIFS('Conciliacion de compuestos'!$D$2:$D$13,"conciliado",'Conciliacion de compuestos'!$E$2:$E$13,"OK",'Conciliacion de compuestos'!$M$2:$M$13,A77),COUNTIFS('Conciliacion de compuestos'!$D$2:$D$13,"conciliado",'Conciliacion de compuestos'!$E$2:$E$13,"OK",'Conciliacion de compuestos'!$N$2:$N$13,A77),COUNTIFS('Conciliacion de compuestos'!$D$2:$D$13,"conciliado",'Conciliacion de compuestos'!$E$2:$E$13,"OK",'Conciliacion de compuestos'!$O$2:$O$13,A77))>0,IFERROR(TEXTJOIN(CHAR(10),TRUE,FILTER('Conciliacion de compuestos'!$A$2:$A$13,('Conciliacion de compuestos'!$D$2:$D$13="conciliado")*('Conciliacion de compuestos'!$E$2:$E$13="OK")*((('Conciliacion de compuestos'!$M$2:$M$13=A77)+('Conciliacion de compuestos'!$N$2:$N$13=A77)+('Conciliacion de compuestos'!$O$2:$O$13=A77))>0))),""),"") | G77: =IF(I77="conciliado","conciliado","por revisar") | I77: =IF(SUM(COUNTIFS('Conciliacion de compuestos'!$D$2:$D$13,"conciliado",'Conciliacion de compuestos'!$E$2:$E$13,"OK",'Conciliacion de compuestos'!$M$2:$M$13,A77),COUNTIFS('Conciliacion de compuestos'!$D$2:$D$13,"conciliado",'Conciliacion de compuestos'!$E$2:$E$13,"OK",'Conciliacion de compuestos'!$N$2:$N$13,A77),COUNTIFS('Conciliacion de compuestos'!$D$2:$D$13,"conciliado",'Conciliacion de compuestos'!$E$2:$E$13,"OK",'Conciliacion de compuestos'!$O$2:$O$13,A77))>0,"conciliado","por revisar")
...

Sheet Conciliacion de compuestos
A1: Movimientos banco | B1: Movimientos libro_aux | C1: Diferencia | D1: Estado | E1: Validacion | F1: Descripcion | G1: Observacion | H1: ids banco | I1: ids libro_aux | J1: id banco 1 | K1: id banco 2 | L1: id banco 3 | M1: id libro_aux 1 | N1: id libro_aux 2 | O1: id libro_aux 3
A2: 145 | 2026-01-05 | 21,300 | depositos electronicos masterca transaccion 150 | 2026-01-05 | 24,800 | depositos electronicos masterca transaccion | B2: 38 | 2026-01-05 | 46,100 | cardona ospina victo | C2: 0 | D2: por revisar | E2: =IF(D2<>"conciliado","Pendiente",IF(C2<>0,"ERROR: diferencia distinta de cero",IF(OR(AND(J2<>"",SUM(COUNTIFS($D$2:$D$13,"conciliado",$J$2:$J$13,J2),COUNTIFS($D$2:$D$13,"conciliado",$K$2:$K$13,J2),COUNTIFS($D$2:$D$13,"conciliado",$L$2:$L$13,J2))>1),AND(K2<>"",SUM(COUNTIFS($D$2:$D$13,"conciliado",$J$2:$J$13,K2),COUNTIFS($D$2:$D$13,"conciliado",$K$2:$K$13,K2),COUNTIFS($D$2:$D$13,"conciliado",$L$2:$L$13,K2))>1),AND(L2<>"",SUM(COUNTIFS($D$2:$D$13,"conciliado",$J$2:$J$13,L2),COUNTIFS($D$2:$D$13,"conciliado",$K$2:$K$13,L2),COUNTIFS($D$2:$D$13,"conciliado",$L$2:$L$13,L2))>1)),"ERROR: banco ya usado en otro compuesto conciliado",IF(OR(AND(M2<>"",SUM(COUNTIFS($D$2:$D$13,"conciliado",$M$2:$M$13,M2),COUNTIFS($D$2:$D$13,"conciliado",$N$2:$N$13,M2),COUNTIFS($D$2:$D$13,"conciliado",$O$2:$O$13,M2))>1),AND(N2<>"",SUM(COUNTIFS($D$2:$D$13,"conciliado",$M$2:$M$13,N2),COUNTIFS($D$2:$D$13,"conciliado",$N$2:$N$13,N2),COUNTIFS($D$2:$D$13,"conciliado",$O$2:$O$13,N2))>1),AND(O2<>"",SUM(COUNTIFS($D$2:$D$13,"conciliado",$M$2:$M$13,O2),COUNTIFS($D$2:$D$13,"conciliado",$N$2:$N$13,O2),COUNTIFS($D$2:$D$13,"conciliado",$O$2:$O$13,O2))>1)),"ERROR: libro_aux ya usado en otro compuesto conciliado","OK")))) | F2: Posible compuesto detectado por suma exacta en la misma fecha. Revisar antes de conciliar. | H2: 145, 150 | I2: 38 | J2: 145 | K2: 150 | M2: 38
A3: 380 | 2026-01-05 | 21,400 | depositos electronicos masterca transaccion 385 | 2026-01-05 | 20,000 | depositos electronicos masterca transaccion 415 | 2026-01-05 | 22,200 | depositos electronicos masterca transaccion | B3: 46 | 2026-01-05 | 63,600 | guzman rob turcan | C3: 0 | D3: por revisar | E3: =IF(D3<>"conciliado","Pendiente",IF(C3<>0,"ERROR: diferencia distinta de cero",IF(OR(AND(J3<>"",SUM(COUNTIFS($D$2:$D$13,"conciliado",$J$2:$J$13,J3),COUNTIFS($D$2:$D$13,"conciliado",$K$2:$K$13,J3),COUNTIFS($D$2:$D$13,"conciliado",$L$2:$L$13,J3))>1),AND(K3<>"",SUM(COUNTIFS($D$2:$D$13,"conciliado",$J$2:$J$13,K3),COUNTIFS($D$2:$D$13,"conciliado",$K$2:$K$13,K3),COUNTIFS($D$2:$D$13,"conciliado",$L$2:$L$13,K3))>1),AND(L3<>"",SUM(COUNTIFS($D$2:$D$13,"conciliado",$J$2:$J$13,L3),COUNTIFS($D$2:$D$13,"conciliado",$K$2:$K$13,L3),COUNTIFS($D$2:$D$13,"conciliado",$L$2:$L$13,L3))>1)),"ERROR: banco ya usado en otro compuesto conciliado",IF(OR(AND(M3<>"",SUM(COUNTIFS($D$2:$D$13,"conciliado",$M$2:$M$13,M3),COUNTIFS($D$2:$D$13,"conciliado",$N$2:$N$13,M3),COUNTIFS($D$2:$D$13,"conciliado",$O$2:$O$13,M3))>1),AND(N3<>"",SUM(COUNTIFS($D$2:$D$13,"conciliado",$M$2:$M$13,N3),COUNTIFS($D$2:$D$13,"conciliado",$N$2:$N$13,N3),COUNTIFS($D$2:$D$13,"conciliado",$O$2:$O$13,N3))>1),AND(O3<>"",SUM(COUNTIFS($D$2:$D$13,"conciliado",$M$2:$M$13,O3),COUNTIFS($D$2:$D$13,"conciliado",$N$2:$N$13,O3),COUNTIFS($D$2:$D$13,"conciliado",$O$2:$O$13,O3))>1)),"ERROR: libro_aux ya usado en otro compuesto conciliado","OK")))) | F3: Posible compuesto detectado por suma exacta en la misma fecha. Revisar antes de conciliar. | H3: 380, 385, 415 | I3: 46 | J3: 380 | K3: 385 | L3: 415 | M3: 46
A4: 145 | 2026-01-05 | 21,300 | depositos electronicos masterca transaccion 175 | 2026-01-05 | 45,500 | depositos electronicos masterca transaccion 375 | 2026-01-05 | 23,700 | depositos electronicos masterca transaccion | B4: 44 | 2026-01-05 | 90,500 | francisco meza meza | C4: 0 | D4: por revisar | E4: =IF(D4<>"conciliado","Pendiente",IF(C4<>0,"ERROR: diferencia distinta de cero",IF(OR(AND(J4<>"",SUM(COUNTIFS($D$2:$D$13,"conciliado",$J$2:$J$13,J4),COUNTIFS($D$2:$D$13,"conciliado",$K$2:$K$13,J4),COUNTIFS($D$2:$D$13,"conciliado",$L$2:$L$13,J4))>1),AND(K4<>"",SUM(COUNTIFS($D$2:$D$13,"conciliado",$J$2:$J$13,K4),COUNTIFS($D$2:$D$13,"conciliado",$K$2:$K$13,K4),COUNTIFS($D$2:$D$13,"conciliado",$L$2:$L$13,K4))>1),AND(L4<>"",SUM(COUNTIFS($D$2:$D$13,"conciliado",$J$2:$J$13,L4),COUNTIFS($D$2:$D$13,"conciliado",$K$2:$K$13,L4),COUNTIFS($D$2:$D$13,"conciliado",$L$2:$L$13,L4))>1)),"ERROR: banco ya usado en otro compuesto conciliado",IF(OR(AND(M4<>"",SUM(COUNTIFS($D$2:$D$13,"conciliado",$M$2:$M$13,M4),COUNTIFS($D$2:$D$13,"conciliado",$N$2:$N$13,M4),COUNTIFS($D$2:$D$13,"conciliado",$O$2:$O$13,M4))>1),AND(N4<>"",SUM(COUNTIFS($D$2:$D$13,"conciliado",$M$2:$M$13,N4),COUNTIFS($D$2:$D$13,"conciliado",$N$2:$N$13,N4),COUNTIFS($D$2:$D$13,"conciliado",$O$2:$O$13,N4))>1),AND(O4<>"",SUM(COUNTIFS($D$2:$D$13,"conciliado",$M$2:$M$13,O4),COUNTIFS($D$2:$D$13,"conciliado",$N$2:$N$13,O4),COUNTIFS($D$2:$D$13,"conciliado",$O$2:$O$13,O4))>1)),"ERROR: libro_aux ya usado en otro compuesto conciliado","OK")))) | F4: Posible compuesto detectado por suma exacta en la misma fecha. Revisar antes de conciliar. | H4: 145, 175, 375 | I4: 44 | J4: 145 | K4: 175 | L4: 375 | M4: 44
A5: 680 | 2026-01-13 | 23,100 | consignacion credibanco d e 770 | 2026-01-13 | 30,000 | consignacion credibanco d e 790 | 2026-01-13 | 20,300 | consignacion credibanco d e | B5: 125 | 2026-01-13 | 73,400 | al daira lopez trejo | C5: 0 | D5: por revisar | E5: =IF(D5<>"conciliado","Pendiente",IF(C5<>0,"ERROR: diferencia distinta de cero",IF(OR(AND(J5<>"",SUM(COUNTIFS($D$2:$D$13,"conciliado",$J$2:$J$13,J5),COUNTIFS($D$2:$D$13,"conciliado",$K$2:$K$13,J5),COUNTIFS($D$2:$D$13,"conciliado",$L$2:$L$13,J5))>1),AND(K5<>"",SUM(COUNTIFS($D$2:$D$13,"conciliado",$J$2:$J$13,K5),COUNTIFS($D$2:$D$13,"conciliado",$K$2:$K$13,K5),COUNTIFS($D$2:$D$13,"conciliado",$L$2:$L$13,K5))>1),AND(L5<>"",SUM(COUNTIFS($D$2:$D$13,"conciliado",$J$2:$J$13,L5),COUNTIFS($D$2:$D$13,"conciliado",$K$2:$K$13,L5),COUNTIFS($D$2:$D$13,"conciliado",$L$2:$L$13,L5))>1)),"ERROR: banco ya usado en otro compuesto conciliado",IF(OR(AND(M5<>"",SUM(COUNTIFS($D$2:$D$13,"conciliado",$M$2:$M$13,M5),COUNTIFS($D$2:$D$13,"conciliado",$N$2:$N$13,M5),COUNTIFS($D$2:$D$13,"conciliado",$O$2:$O$13,M5))>1),AND(N5<>"",SUM(COUNTIFS($D$2:$D$13,"conciliado",$M$2:$M$13,N5),COUNTIFS($D$2:$D$13,"conciliado",$N$2:$N$13,N5),COUNTIFS($D$2:$D$13,"conciliado",$O$2:$O$13,N5))>1),AND(O5<>"",SUM(COUNTIFS($D$2:$D$13,"conciliado",$M$2:$M$13,O5),COUNTIFS($D$2:$D$13,"conciliado",$N$2:$N$13,O5),COUNTIFS($D$2:$D$13,"conciliado",$O$2:$O$13,O5))>1)),"ERROR: libro_aux ya usado en otro compuesto conciliado","OK")))) | F5: Posible compuesto detectado por suma exacta en la misma fecha. Revisar antes de conciliar. | H5: 680, 770, 790 | I5: 125 | J5: 680 | K5: 770 | L5: 790 | M5: 125
